Workbook

Sheet Cover Page
A1: NBFC SECTOR BACKTESTING PROJECT
A2: Comprehensive Strategy Performance Analysis | FY 2025–26
A4: Submitted By | B4: Vishv Jeet Singh Thakur
A5: Submitted To | B5: Nikesh Ruparel
A6: College | B6: UPES
A7: Branch | B7: MBA in Strategic Financial Management in collaboration with EY
A8: Batch | B8: F4- Jun-2026
A9: Sector Allocated | B9: NBFC – General
A11: NBFC Sector – Company Reference List | FY 2025–26 | Date: 26 June 2026
A12: Company Name | B12: Trading Symbol | C12: Official Category | D12: Market Cap (₹ Cr)
A13: Aavas Financiers | B13: AAVAS | C13: =IF(D13<20000,"Mid Cap","Large Cap") -> Mid Cap | D13: 11813
A14: Home First Finance Company India | B14: HOMEFIRST | C14: =IF(D14<20000,"Mid Cap","Large Cap") -> Mid Cap | D14: 12456
A15: Five-Star Business Finance | B15: FIVESTAR | C15: =IF(D15<20000,"Mid Cap","Large Cap") -> Mid Cap | D15: 14670
A16: IIFL Finance | B16: IIFL | C16: =IF(D16<20000,"Mid Cap","Large Cap") -> Large Cap | D16: 21679
A17: Manappuram Finance | B17: MANAPPURAM | C17: =IF(D17<20000,"Mid Cap","Large Cap") -> Large Cap | D17: 29918
A18: LIC Housing Finance | B18: LICHSGFIN | C18: =IF(D18<20000,"Mid Cap","Large Cap") -> Large Cap | D18: 30245
A19: Poonawalla Fincorp | B19: POONAWALLA | C19: =IF(D19<20000,"Mid Cap","Large Cap") -> Large Cap | D19: 38768
A20: Mahindra & Mahindra Financial Services | B20: M&MFIN | C20: =IF(D20<20000,"Mid Cap","Large Cap") -> Large Cap | D20: 45668
A21: Sundaram Finance | B21: SUNDARMFIN | C21: =IF(D21<20000,"Mid Cap","Large Cap") -> Large Cap | D21: 51409
A22: L&T Finance | B22: LTF | C22: =IF(D22<20000,"Mid Cap","Large Cap") -> Large Cap | D22: 74915
A23: Aditya Birla Capital | B23: ABCAPITAL | C23: =IF(D23<20000,"Mid Cap","Large Cap") -> Large Cap | D23: 106853
A24: Muthoot Finance | B24: MUTHOOTFIN | C24: =IF(D24<20000,"Mid Cap","Large Cap") -> Large Cap | D24: 121468
... A27: Bajaj Finance | B27: BAJFINANCE | C27: =IF(D27<20000,"Mid Cap","Large Cap") -> Large Cap | D27: 610393
A28: Sector Average | D28: =AVERAGE(D13:D27) -> 104428.4
A30: 📌 Note: Mid Cap = Market Cap < ₹20,000 Cr | Large Cap = Market Cap ≥ ₹20,000 Cr | Companies sorted by ascending market capitalization

Sheet Content
A1: TABLE OF CONTENTS
A2: NBFC Sector Backtesting Project | FY 2025–26 | 10 Strategies × 15 NBFC Stocks
A4: # | B4: Section | C4: What's Inside | D4: Go To
A5: 1 | B5: Cover Page | C5: Project details, submission info & NBFC company reference list | D5: Open sheet ▸
A6: 2 | B6: Vwap | C6: VWAP Intraday Strategy — quarter-wise Buy/Sell backtest results | D6: Open sheet ▸
A7: 3 | B7: SuperTrend | C7: SuperTrend Intraday Strategy — quarter-wise Buy/Sell backtest results | D7: Open sheet ▸
A8: 4 | B8: MA | C8: Moving Average Intraday Strategy — quarter-wise Buy/Sell backtest results | D8: Open sheet ▸
A9: 5 | B9: MACD | C9: MACD Intraday Strategy — quarter-wise Buy/Sell backtest results | D9: Open sheet ▸
A10: 6 | B10: RSI | C10: RSI Intraday Strategy — quarter-wise Buy/Sell backtest results | D10: Open sheet ▸
A11: 7 | B11: Stochastic RSI | C11: Stochastic RSI Intraday Strategy — quarter-wise Buy/Sell backtest results | D11: Open sheet ▸
A12: 8 | B12: BB | C12: Bollinger Bands Intraday Strategy — quarter-wise Buy/Sell backtest results | D12: Open sheet ▸
A13: 9 | B13: AO | C13: Awesome Oscillator Intraday Strategy — quarter-wise Buy/Sell backtest results | D13: Open sheet ▸
A14: 10 | B14: PPS | C14: Pivot Point Standard Intraday Strategy — quarter-wise Buy/Sell backtest results | D14: Open sheet ▸
A15: 11 | B15: WA | C15: Williams Alligator Intraday Strategy — quarter-wise Buy/Sell backtest results | D15: Open sheet ▸
A16: 12 | B16: Results | C16: Final leaderboard — all 10 strategies ranked by FY net P&L, with key takeaways | D16: Open sheet ▸
A18: 📌 Note: Click "Open sheet ▸" to jump directly to a section. Each strategy sheet is broken out by quarter (Q1–Q4) plus a Financial Year summary.

Sheet Vwap
A1: NBFC – General Sector | Backtesting Report
A2: Student: Vishv Jeet Singh Thakur | Institution: UPES | Strategy: VWAP Intraday (5-Minute) | Time: 9:15 AM – 3:00 PM | Financial Year: FY 2025–26
A4: Q1 (Quarter 1): April 1, 2025 – June 30, 2025
A5: BUY / LONG CALL SIDE | H5: SELL / SHORT CALL SIDE
A6: Company Name | B6: Segment | C6: P&L (₹) | D6: Wins | E6: Losses | F6: Total Trades | H6: Company Name | I6: Segment | J6: P&L (₹) | K6: Wins | L6: Losses | M6: Total Trades
A7: Aavas Financiers | B7: NSE | C7: 1229.65 | D7: 36 | E7: 57 | F7: =SUM(D7,E7) -> 93 | H7: Aavas Financiers | I7: NSE | J7: 264.6 | K7: 39 | L7: 52 | M7: =SUM(K7,L7) -> 91
A8: Home First Finance Company India | B8: NSE | C8: 4538.1 | D8: 44 | E8: 52 | F8: =SUM(D8,E8) -> 96 | H8: Home First Finance Company India | I8: NSE | J8: -1938.55 | K8: 36 | L8: 69 | M8: =SUM(K8,L8) -> 105
A9: Five-Star Business Finance | B9: NSE | C9: 621.9 | D9: 39 | E9: 56 | F9: =SUM(D9,E9) -> 95 | H9: Five-Star Business Finance | I9: NSE | J9: -2686.9 | K9: 31 | L9: 61 | M9: =SUM(K9,L9) -> 92
A10: IIFL Finance | B10: NSE | C10: 303.2 | D10: 43 | E10: 73 | F10: =SUM(D10,E10) -> 116 | H10: IIFL Finance | I10: NSE | J10: -2292 | K10: 44 | L10: 73 | M10: =SUM(K10,L10) -> 117
A11: Manappuram Finance | B11: NSE | C11: -433.85 | D11: 35 | E11: 50 | F11: =SUM(D11,E11) -> 85 | H11: Manappuram Finance | I11: NSE | J11: -689.94 | K11: 36 | L11: 48 | M11: =SUM(K11,L11) -> 84
A12: LIC Housing Finance | B12: NSE | C12: 1107.9 | D12: 36 | E12: 54 | F12: =SUM(D12,E12) -> 90 | H12: LIC Housing Finance | I12: NSE | J12: 421.55 | K12: 36 | L12: 48 | M12: =SUM(K12,L12) -> 84
A13: Poonawalla Fincorp | B13: NSE | C13: 1735.5 | D13: 45 | E13: 56 | F13: =SUM(D13,E13) -> 101 | H13: Poonawalla Fincorp | I13: NSE | J13: -6259.9 | K13: 30 | L13: 78 | M13: =SUM(K13,L13) -> 108
A14: Mahindra & Mahindra Financial Services | B14: NSE | C14: -2159.8 | D14: 34 | E14: 55 | F14: =SUM(D14,E14) -> 89 | H14: Mahindra & Mahindra Financial Services | I14: NSE | J14: -774.4 | K14: 33 | L14: 48 | M14: =SUM(K14,L14) -> 81
A15: Sundaram Finance | B15: NSE | C15: 1625.6 | D15: 39 | E15: 56 | F15: =SUM(D15,E15) -> 95 | H15: Sundaram Finance | I15: NSE | J15: -2078.2 | K15: 27 | L15: 61 | M15: =SUM(K15,L15) -> 88
A16: L&T Finance | B16: NSE | C16: 1905.93 | D16: 39 | E16: 51 | F16: =SUM(D16,E16) -> 90 | H16: L&T Finance | I16: NSE | J16: -2328.34 | K16: 29 | L16: 61 | M16: =SUM(K16,L16) -> 90
A17: Aditya Birla Capital | B17: NSE | C17: 2749.69 | D17: 45 | E17: 53 | F17: =SUM(D17,E17) -> 98 | H17: Aditya Birla Capital | I17: NSE | J17: -3002.83 | K17: 34 | L17: 67 | M17: =SUM(K17,L17) -> 101
A18: Muthoot Finance | B18: NSE | C18: 2557.65 | D18: 42 | E18: 46 | F18: =SUM(D18,E18) -> 88 | H18: Muthoot Finance | I18: NSE | J18: -4103.6 | K18: 26 | L18: 61 | M18: =SUM(K18,L18) -> 87
... A21: Bajaj Finance | B21: NSE | C21: 398.95 | D21: 35 | E21: 44 | F21: =SUM(D21,E21) -> 79 | H21: Bajaj Finance | I21: NSE | J21: -1344.8 | K21: 31 | L21: 47 | M21: =SUM(K21,L21) -> 78
A22: TOTAL | C22: =SUM(C7:C21) -> 15615.72 | D22: =SUM(D7:D21) -> 582 | E22: =SUM(E7:E21) -> 817 | F22: =SUM(F7:F21) -> 1399 | H22: TOTAL | J22: =SUM(J7:J21) -> -25519.86 | K22: =SUM(K7:K21) -> 507 | L22: =SUM(L7:L21) -> 871 | M22: =SUM(M7:M21) -> 1378
A24: Q2 (Quarter 2): July 2, 2025 – September 30, 2025
A25: BUY / LONG CALL SIDE | H25: SELL / SHORT CALL SIDE
A26: Company Name | B26: Segment | C26: P&L (₹) | D26: Wins | E26: Losses | F26: Total Trades | H26: Company Name | I26: Segment | J26: P&L (₹) | K26: Wins | L26: Losses | M26: Total Trades
A27: Aavas Financiers | B27: NSE | C27: -1746.2 | D27: 29 | E27: 55 | F27: =SUM(D27,E27) -> 84 | H27: Aavas Financiers | I27: NSE | J27: 4687.35 | K27: 43 | L27: 37 | M27: =SUM(K27,L27) -> 80
A28: Home First Finance Company India | B28: NSE | C28: 218.35 | D28: 37 | E28: 55 | F28: =SUM(D28,E28) -> 92 | H28: Home First Finance Company India | I28: NSE | J28: -1364.45 | K28: 37 | L28: 68 | M28: =SUM(K28,L28) -> 105
A29: Five-Star Business Finance | B29: NSE | C29: -1278.25 | D29: 35 | E29: 55 | F29: =SUM(D29,E29) -> 90 | H29: Five-Star Business Finance | I29: NSE | J29: 708.4 | K29: 38 | L29: 51 | M29: =SUM(K29,L29) -> 89
A30: IIFL Finance | B30: NSE | C30: 589 | D30: 40 | E30: 56 | F30: =SUM(D30,E30) -> 96 | H30: IIFL Finance | I30: NSE | J30: 1937.05 | K30: 44 | L30: 52 | M30: =SUM(K30,L30) -> 96
A31: Manappuram Finance | B31: NSE | C31: 495.85 | D31: 37 | E31: 48 | F31: =SUM(D31,E31) -> 85 | H31: Manappuram Finance | I31: NSE | J31: 3307.75 | K31: 44 | L31: 53 | M31: =SUM(K31,L31) -> 97
A32: LIC Housing Finance | B32: NSE | C32: -1021.5 | D32: 28 | E32: 41 | F32: =SUM(D32,E32) -> 69 | H32: LIC Housing Finance | I32: NSE | J32: 3516.65 | K32: 43 | L32: 27 | M32: =SUM(K32,L32) -> 70
A33: Poonawalla Fincorp | B33: NSE | C33: -123.9 | D33: 37 | E33: 59 | F33: =SUM(D33,E33) -> 96 | H33: Poonawalla Fincorp | I33: NSE | J33: -70.25 | K33: 39 | L33: 49 | M33: =SUM(K33,L33) -> 88
A34: Mahindra & Mahindra Financial Services | B34: NSE | C34: 1101.05 | D34: 38 | E34: 51 | F34: =SUM(D34,E34) -> 89 | H34: Mahindra & Mahindra Financial Services | I34: NSE | J34: -440.3 | K34: 36 | L34: 46 | M34: =SUM(K34,L34) -> 82
A35: Sundaram Finance | B35: NSE | C35: 0.9 | D35: 37 | E35: 47 | F35: =SUM(D35,E35) -> 84 | H35: Sundaram Finance | I35: NSE | J35: 421.15 | K35: 32 | L35: 47 | M35: =SUM(K35,L35) -> 79
A36: L&T Finance | B36: NSE | C36: 1870.58 | D36: 41 | E36: 48 | F36: =SUM(D36,E36) -> 89 | H36: L&T Finance | I36: NSE | J36: -140.63 | K36: 41 | L36: 51 | M36: =SUM(K36,L36) -> 92
A37: Aditya Birla Capital | B37: NSE | C37: -343.6 | D37: 33 | E37: 53 | F37: =SUM(D37,E37) -> 86 | H37: Aditya Birla Capital | I37: NSE | J37: 5241.8 | K37: 44 | L37: 37 | M37: =SUM(K37,L37) -> 81
A38: Muthoot Finance | B38: NSE | C38: 1021.65 | D38: 38 | E38: 46 | F38: =SUM(D38,E38) -> 84 | H38: Muthoot Finance | I38: NSE | J38: -1070.3 | K38: 35 | L38: 52 | M38: =SUM(K38,L38) -> 87
... A41: Bajaj Finance | B41: NSE | C41: 1098.95 | D41: 39 | E41: 36 | F41: =SUM(D41,E41) -> 75 | H41: Bajaj Finance | I41: NSE | J41: 246.3 | K41: 32 | L41: 40 | M41: =SUM(K41,L41) -> 72
A42: TOTAL | C42: =SUM(C27:C41) -> 692.33 | D42: =SUM(D27:D41) -> 536 | E42: =SUM(E27:E41) -> 747 | F42: =SUM(F27:F41) -> 1283 | H42: TOTAL | J42: =SUM(J27:J41) -> 18475.32 | K42: =SUM(K27:K41) -> 583 | L42: =SUM(L27:L41) -> 692 | M42: =SUM(M27:M41) -> 1275
A44: Q3 (Quarter 3): October 2, 2025 – December 31, 2025
A45: BUY / LONG CALL SIDE | H45: SELL / SHORT CALL SIDE
A46: Company Name | B46: Segment | C46: P&L (₹) | D46: Wins | E46: Losses | F46: Total Trades | H46: Company Name | I46: Segment | J46: P&L (₹) | K46: Wins | L46: Losses | M46: Total Trades
A47: Aavas Financiers | B47: NSE | C47: 185.5 | D47: 33 | E47: 45 | F47: =SUM(D47,E47) -> 78 | H47: Aavas Financiers | I47: NSE | J47: 48.8 | K47: 36 | L47: 42 | M47: =SUM(K47,L47) -> 78
...

Sheet SuperTrend
A1: NBFC – General Sector | Backtesting Report
A2: Student: Vishv Jeet Singh Thakur | Institution: UPES | Strategy: SuperTrend Intraday (5-Minute) | Time: 9:15 AM – 3:00 PM | FY 2025–26
A4: Q1 (Quarter 1): April 1, 2025 – June 30, 2025
A5: BUY / LONG CALL SIDE | H5: SELL / SHORT CALL SIDE
A6: Company Name | B6: Segment | C6: P&L (₹) | D6: Wins | E6: Losses | F6: Total Trades | H6: Company Name | I6: Segment | J6: P&L (₹) | K6: Wins | L6: Losses | M6: Total Trades
A7: Aavas Financiers | B7: NSE | C7: -280.4 | D7: 18 | E7: 30 | F7: =SUM(D7,E7) -> 48 | H7: Aavas Financiers | I7: NSE | J7: -1082.5 | K7: 18 | L7: 30 | M7: =SUM(K7,L7) -> 48
A8: Home First Finance Company India | B8: NSE | C8: 620.75 | D8: 21 | E8: 32 | F8: =SUM(D8,E8) -> 53 | H8: Home First Finance Company India | I8: NSE | J8: -2712.6 | K8: 13 | L8: 35 | M8: =SUM(K8,L8) -> 48
A9: Five-Star Business Finance | B9: NSE | C9: 389.55 | D9: 16 | E9: 25 | F9: =SUM(D9,E9) -> 41 | H9: Five-Star Business Finance | I9: NSE | J9: -1140.85 | K9: 15 | L9: 29 | M9: =SUM(K9,L9) -> 44
A10: IIFL Finance | B10: NSE | C10: 837.4 | D10: 23 | E10: 31 | F10: =SUM(D10,E10) -> 54 | H10: IIFL Finance | I10: NSE | J10: 688.3 | K10: 22 | L10: 31 | M10: =SUM(K10,L10) -> 53
A11: Manappuram Finance | B11: NSE | C11: 39.53 | D11: 24 | E11: 27 | F11: =SUM(D11,E11) -> 51 | H11: Manappuram Finance | I11: NSE | J11: -2462.54 | K11: 13 | L11: 33 | M11: =SUM(K11,L11) -> 46
A12: LIC Housing Finance | B12: NSE | C12: -957.5 | D12: 18 | E12: 29 | F12: =SUM(D12,E12) -> 47 | H12: LIC Housing Finance | I12: NSE | J12: 1427 | K12: 27 | L12: 21 | M12: =SUM(K12,L12) -> 48
A13: Poonawalla Fincorp | B13: NSE | C13: -1501.35 | D13: 25 | E13: 33 | F13: =SUM(D13,E13) -> 58 | H13: Poonawalla Fincorp | I13: NSE | J13: -2030.5 | K13: 16 | L13: 39 | M13: =SUM(K13,L13) -> 55
A14: Mahindra & Mahindra Financial Services | B14: NSE | C14: -1753.05 | D14: 18 | E14: 35 | F14: =SUM(D14,E14) -> 53 | H14: Mahindra & Mahindra Financial Services | I14: NSE | J14: -813.9 | K14: 20 | L14: 32 | M14: =SUM(K14,L14) -> 52
A15: Sundaram Finance | B15: NSE | C15: 2491.55 | D15: 26 | E15: 27 | F15: =SUM(D15,E15) -> 53 | H15: Sundaram Finance | I15: NSE | J15: -1571.1 | K15: 15 | L15: 33 | M15: =SUM(K15,L15) -> 48
A16: L&T Finance | B16: NSE | C16: 2787.74 | D16: 23 | E16: 25 | F16: =SUM(D16,E16) -> 48 | H16: L&T Finance | I16: NSE | J16: 41.61 | K16: 24 | L16: 32 | M16: =SUM(K16,L16) -> 56
A17: Aditya Birla Capital | B17: NSE | C17: 522.15 | D17: 22 | E17: 32 | F17: =SUM(D17,E17) -> 54 | H17: Aditya Birla Capital | I17: NSE | J17: -1671.84 | K17: 20 | L17: 34 | M17: =SUM(K17,L17) -> 54
A18: Muthoot Finance | B18: NSE | C18: 1544.2 | D18: 26 | E18: 21 | F18: =SUM(D18,E18) -> 47 | H18: Muthoot Finance | I18: NSE | J18: -1775.65 | K18: 18 | L18: 33 | M18: =SUM(K18,L18) -> 51
... A21: Bajaj Finance | B21: NSE | C21: 1560.4 | D21: 27 | E21: 18 | F21: =SUM(D21,E21) -> 45 | H21: Bajaj Finance | I21: NSE | J21: -787.8 | K21: 20 | L21: 25 | M21: =SUM(K21,L21) -> 45
A22: TOTAL | C22: =SUM(C7:C21) -> 5779.27 | D22: =SUM(D7:D21) -> 327 | E22: =SUM(E7:E21) -> 424 | F22: =SUM(F7:F21) -> 751 | H22: TOTAL | J22: =SUM(J7:J21) -> -12505.27 | K22: =SUM(K7:K21) -> 284 | L22: =SUM(L7:L21) -> 459 | M22: =SUM(M7:M21) -> 743
A24: Q2 (Quarter 2): July 2, 2025 – September 30, 2025
A25: BUY / LONG CALL SIDE | H25: SELL / SHORT CALL SIDE
A26: Company Name | B26: Segment | C26: P&L (₹) | D26: Wins | E26: Losses | F26: Total Trades | H26: Company Name | I26: Segment | J26: P&L (₹) | K26: Wins | L26: Losses | M26: Total Trades
A27: Aavas Financiers | B27: NSE | C27: -549.1 | D27: 18 | E27: 30 | F27: =SUM(D27,E27) -> 48 | H27: Aavas Financiers | I27: NSE | J27: 27.9 | K27: 17 | L27: 29 | M27: =SUM(K27,L27) -> 46
A28: Home First Finance Company India | B28: NSE | C28: 1015.55 | D28: 19 | E28: 19 | F28: =SUM(D28,E28) -> 38 | H28: Home First Finance Company India | I28: NSE | J28: 463 | K28: 16 | L28: 18 | M28: =SUM(K28,L28) -> 34
A29: Five-Star Business Finance | B29: NSE | C29: -633.65 | D29: 21 | E29: 32 | F29: =SUM(D29,E29) -> 53 | H29: Five-Star Business Finance | I29: NSE | J29: -427.35 | K29: 21 | L29: 33 | M29: =SUM(K29,L29) -> 54
A30: IIFL Finance | B30: NSE | C30: 683.25 | D30: 21 | E30: 30 | F30: =SUM(D30,E30) -> 51 | H30: IIFL Finance | I30: NSE | J30: 728.2 | K30: 27 | L30: 27 | M30: =SUM(K30,L30) -> 54
A31: Manappuram Finance | B31: NSE | C31: -1799.35 | D31: 22 | E31: 36 | F31: =SUM(D31,E31) -> 58 | H31: Manappuram Finance | I31: NSE | J31: 1731.25 | K31: 30 | L31: 30 | M31: =SUM(K31,L31) -> 60
A32: LIC Housing Finance | B32: NSE | C32: -1412.35 | D32: 18 | E32: 30 | F32: =SUM(D32,E32) -> 48 | H32: LIC Housing Finance | I32: NSE | J32: 686.85 | K32: 30 | L32: 25 | M32: =SUM(K32,L32) -> 55
A33: Poonawalla Fincorp | B33: NSE | C33: 2170.7 | D33: 30 | E33: 23 | F33: =SUM(D33,E33) -> 53 | H33: Poonawalla Fincorp | I33: NSE | J33: 1324.15 | K33: 22 | L33: 27 | M33: =SUM(K33,L33) -> 49
A34: Mahindra & Mahindra Financial Services | B34: NSE | C34: 2365.3 | D34: 31 | E34: 26 | F34: =SUM(D34,E34) -> 57 | H34: Mahindra & Mahindra Financial Services | I34: NSE | J34: -147.55 | K34: 21 | L34: 26 | M34: =SUM(K34,L34) -> 47
A35: Sundaram Finance | B35: NSE | C35: 731.25 | D35: 24 | E35: 21 | F35: =SUM(D35,E35) -> 45 | H35: Sundaram Finance | I35: NSE | J35: 1049.55 | K35: 19 | L35: 28 | M35: =SUM(K35,L35) -> 47
A36: L&T Finance | B36: NSE | C36: 650.19 | D36: 26 | E36: 38 | F36: =SUM(D36,E36) -> 64 | H36: L&T Finance | I36: NSE | J36: 283.66 | K36: 28 | L36: 31 | M36: =SUM(K36,L36) -> 59
A37: Aditya Birla Capital | B37: NSE | C37: 471.55 | D37: 27 | E37: 34 | F37: =SUM(D37,E37) -> 61 | H37: Aditya Birla Capital | I37: NSE | J37: 383.3 | K37: 28 | L37: 31 | M37: =SUM(K37,L37) -> 59
A38: Muthoot Finance | B38: NSE | C38: 400.4 | D38: 27 | E38: 31 | F38: =SUM(D38,E38) -> 58 | H38: Muthoot Finance | I38: NSE | J38: -831.75 | K38: 24 | L38: 31 | M38: =SUM(K38,L38) -> 55
... A41: Bajaj Finance | B41: NSE | C41: -1500.65 | D41: 20 | E41: 30 | F41: =SUM(D41,E41) -> 50 | H41: Bajaj Finance | I41: NSE | J41: 824.95 | K41: 25 | L41: 20 | M41: =SUM(K41,L41) -> 45
A42: TOTAL | C42: =SUM(C27:C41) -> 2517.64 | D42: =SUM(D27:D41) -> 348 | E42: =SUM(E27:E41) -> 440 | F42: =SUM(F27:F41) -> 788 | H42: TOTAL | J42: =SUM(J27:J41) -> 6879.66 | K42: =SUM(K27:K41) -> 359 | L42: =SUM(L27:L41) -> 407 | M42: =SUM(M27:M41) -> 766
A44: Q3 (Quarter 3): October 2, 2025 – December 31, 2025
A45: BUY / LONG CALL SIDE | H45: SELL / SHORT CALL SIDE
A46: Company Name | B46: Segment | C46: P&L (₹) | D46: Wins | E46: Losses | F46: Total Trades | H46: Company Name | I46: Segment | J46: P&L (₹) | K46: Wins | L46: Losses | M46: Total Trades
A47: Aavas Financiers | B47: NSE | C47: -562.35 | D47: 20 | E47: 29 | F47: =SUM(D47,E47) -> 49 | H47: Aavas Financiers | I47: NSE | J47: -84.2 | K47: 21 | L47: 29 | M47: =SUM(K47,L47) -> 50
...

Sheet MA
A1: NBFC – General Sector | Backtesting Report
A2: Student: Vishv Jeet Singh Thakur | Institution: UPES | Strategy: Moving Average (MA) Intraday (5-Minute) | Time: 9:15 AM – 3:00 PM | FY 2025–26
A4: Q1 (Quarter 1): April 1, 2025 – June 30, 2025
A5: BUY / LONG CALL SIDE | H5: SELL / SHORT CALL SIDE
A6: Company Name | B6: Segment | C6: P&L (₹) | D6: Wins | E6: Losses | F6: Total Trades | H6: Company Name | I6: Segment | J6: P&L (₹) | K6: Wins | L6: Losses | M6: Total Trades
A7: Aavas Financiers | B7: NSE | C7: 668.65 | D7: 14 | E7: 17 | F7: =SUM(D7,E7) -> 31 | H7: Aavas Financiers | I7: NSE | J7: 134.6 | K7: 15 | L7: 16 | M7: =SUM(K7,L7) -> 31
A8: Home First Finance Company India | B8: NSE | C8: 1217.55 | D8: 16 | E8: 19 | F8: =SUM(D8,E8) -> 35 | H8: Home First Finance Company India | I8: NSE | J8: -1811.3 | K8: 10 | L8: 23 | M8: =SUM(K8,L8) -> 33
A9: Five-Star Business Finance | B9: NSE | C9: -201.55 | D9: 6 | E9: 10 | F9: =SUM(D9,E9) -> 16 | H9: Five-Star Business Finance | I9: NSE | J9: 458.9 | K9: 8 | L9: 13 | M9: =SUM(K9,L9) -> 21
A10: IIFL Finance | B10: NSE | C10: 5.55 | D10: 18 | E10: 26 | F10: =SUM(D10,E10) -> 44 | H10: IIFL Finance | I10: NSE | J10: 398.9 | K10: 19 | L10: 24 | M10: =SUM(K10,L10) -> 43
A11: Manappuram Finance | B11: NSE | C11: 165.21 | D11: 12 | E11: 20 | F11: =SUM(D11,E11) -> 32 | H11: Manappuram Finance | I11: NSE | J11: -904.93 | K11: 14 | L11: 22 | M11: =SUM(K11,L11) -> 36
A12: LIC Housing Finance | B12: NSE | C12: 1377 | D12: 20 | E12: 16 | F12: =SUM(D12,E12) -> 36 | H12: LIC Housing Finance | I12: NSE | J12: -419.1 | K12: 13 | L12: 19 | M12: =SUM(K12,L12) -> 32
A13: Poonawalla Fincorp | B13: NSE | C13: 64.25 | D13: 17 | E13: 21 | F13: =SUM(D13,E13) -> 38 | H13: Poonawalla Fincorp | I13: NSE | J13: -1056 | K13: 15 | L13: 21 | M13: =SUM(K13,L13) -> 36
A14: Mahindra & Mahindra Financial Services | B14: NSE | C14: -510.3 | D14: 14 | E14: 20 | F14: =SUM(D14,E14) -> 34 | H14: Mahindra & Mahindra Financial Services | I14: NSE | J14: 843.05 | K14: 16 | L14: 19 | M14: =SUM(K14,L14) -> 35
A15: Sundaram Finance | B15: NSE | C15: 1177.45 | D15: 16 | E15: 13 | F15: =SUM(D15,E15) -> 29 | H15: Sundaram Finance | I15: NSE | J15: 110.85 | K15: 13 | L15: 20 | M15: =SUM(K15,L15) -> 33
A16: L&T Finance | B16: NSE | C16: 814.41 | D16: 13 | E16: 19 | F16: =SUM(D16,E16) -> 32 | H16: L&T Finance | I16: NSE | J16: 892.8 | K16: 13 | L16: 16 | M16: =SUM(K16,L16) -> 29
A17: Aditya Birla Capital | B17: NSE | C17: 2354.17 | D17: 18 | E17: 16 | F17: =SUM(D17,E17) -> 34 | H17: Aditya Birla Capital | I17: NSE | J17: -156.31 | K17: 13 | L17: 18 | M17: =SUM(K17,L17) -> 31
A18: Muthoot Finance | B18: NSE | C18: 1034.85 | D18: 17 | E18: 10 | F18: =SUM(D18,E18) -> 27 | H18: Muthoot Finance | I18: NSE | J18: -1457.25 | K18: 9 | L18: 22 | M18: =SUM(K18,L18) -> 31
... A21: Bajaj Finance | B21: NSE | C21: 850.65 | D21: 17 | E21: 13 | F21: =SUM(D21,E21) -> 30 | H21: Bajaj Finance | I21: NSE | J21: -637.65 | K21: 15 | L21: 18 | M21: =SUM(K21,L21) -> 33
A22: TOTAL | C22: =SUM(C7:C21) -> 9635.24 | D22: =SUM(D7:D21) -> 228 | E22: =SUM(E7:E21) -> 250 | F22: =SUM(F7:F21) -> 478 | H22: TOTAL | J22: =SUM(J7:J21) -> -3935.09 | K22: =SUM(K7:K21) -> 198 | L22: =SUM(L7:L21) -> 286 | M22: =SUM(M7:M21) -> 484
A24: Q2 (Quarter 2): July 2, 2025 – September 30, 2025
A25: BUY / LONG CALL SIDE | H25: SELL / SHORT CALL SIDE
A26: Company Name | B26: Segment | C26: P&L (₹) | D26: Wins | E26: Losses | F26: Total Trades | H26: Company Name | I26: Segment | J26: P&L (₹) | K26: Wins | L26: Losses | M26: Total Trades
A27: Aavas Financiers | B27: NSE | C27: -685 | D27: 9 | E27: 21 | F27: =SUM(D27,E27) -> 30 | H27: Aavas Financiers | I27: NSE | J27: 1796.7 | K27: 18 | L27: 12 | M27: =SUM(K27,L27) -> 30
A28: Home First Finance Company India | B28: NSE | C28: 98.9 | D28: 11 | E28: 18 | F28: =SUM(D28,E28) -> 29 | H28: Home First Finance Company India | I28: NSE | J28: -1210.85 | K28: 11 | L28: 17 | M28: =SUM(K28,L28) -> 28
A29: Five-Star Business Finance | B29: NSE | C29: -2373.8 | D29: 7 | E29: 27 | F29: =SUM(D29,E29) -> 34 | H29: Five-Star Business Finance | I29: NSE | J29: 1547.2 | K29: 18 | L29: 13 | M29: =SUM(K29,L29) -> 31
A30: IIFL Finance | B30: NSE | C30: 39.35 | D30: 16 | E30: 17 | F30: =SUM(D30,E30) -> 33 | H30: IIFL Finance | I30: NSE | J30: 1719.65 | K30: 20 | L30: 14 | M30: =SUM(K30,L30) -> 34
A31: Manappuram Finance | B31: NSE | C31: -706.8 | D31: 12 | E31: 17 | F31: =SUM(D31,E31) -> 29 | H31: Manappuram Finance | I31: NSE | J31: 359.2 | K31: 15 | L31: 17 | M31: =SUM(K31,L31) -> 32
A32: LIC Housing Finance | B32: NSE | C32: -3075.2 | D32: 8 | E32: 30 | F32: =SUM(D32,E32) -> 38 | H32: LIC Housing Finance | I32: NSE | J32: 1084.3 | K32: 21 | L32: 17 | M32: =SUM(K32,L32) -> 38
A33: Poonawalla Fincorp | B33: NSE | C33: 469.9 | D33: 15 | E33: 20 | F33: =SUM(D33,E33) -> 35 | H33: Poonawalla Fincorp | I33: NSE | J33: 1250.45 | K33: 16 | L33: 17 | M33: =SUM(K33,L33) -> 33
A34: Mahindra & Mahindra Financial Services | B34: NSE | C34: 1784.4 | D34: 22 | E34: 13 | F34: =SUM(D34,E34) -> 35 | H34: Mahindra & Mahindra Financial Services | I34: NSE | J34: -440.2 | K34: 15 | L34: 20 | M34: =SUM(K34,L34) -> 35
A35: Sundaram Finance | B35: NSE | C35: 235 | D35: 13 | E35: 15 | F35: =SUM(D35,E35) -> 28 | H35: Sundaram Finance | I35: NSE | J35: 1981.9 | K35: 16 | L35: 10 | M35: =SUM(K35,L35) -> 26
A36: L&T Finance | B36: NSE | C36: 198.42 | D36: 14 | E36: 24 | F36: =SUM(D36,E36) -> 38 | H36: L&T Finance | I36: NSE | J36: -462.47 | K36: 17 | L36: 19 | M36: =SUM(K36,L36) -> 36
A37: Aditya Birla Capital | B37: NSE | C37: -536.45 | D37: 17 | E37: 26 | F37: =SUM(D37,E37) -> 43 | H37: Aditya Birla Capital | I37: NSE | J37: -275.05 | K37: 21 | L37: 22 | M37: =SUM(K37,L37) -> 43
A38: Muthoot Finance | B38: NSE | C38: 60 | D38: 18 | E38: 22 | F38: =SUM(D38,E38) -> 40 | H38: Muthoot Finance | I38: NSE | J38: -999.8 | K38: 16 | L38: 24 | M38: =SUM(K38,L38) -> 40
... A41: Bajaj Finance | B41: NSE | C41: -177.85 | D41: 16 | E41: 14 | F41: =SUM(D41,E41) -> 30 | H41: Bajaj Finance | I41: NSE | J41: 1464.15 | K41: 19 | L41: 10 | M41: =SUM(K41,L41) -> 29
A42: TOTAL | C42: =SUM(C27:C41) -> -4798.08 | D42: =SUM(D27:D41) -> 210 | E42: =SUM(E27:E41) -> 300 | F42: =SUM(F27:F41) -> 510 | H42: TOTAL | J42: =SUM(J27:J41) -> 9800.33 | K42: =SUM(K27:K41) -> 260 | L42: =SUM(L27:L41) -> 247 | M42: =SUM(M27:M41) -> 507
A44: Q3 (Quarter 3): October 2, 2025 – December 31, 2025
A45: BUY / LONG CALL SIDE | H45: SELL / SHORT CALL SIDE
A46: Company Name | B46: Segment | C46: P&L (₹) | D46: Wins | E46: Losses | F46: Total Trades | H46: Company Name | I46: Segment | J46: P&L (₹) | K46: Wins | L46: Losses | M46: Total Trades
A47: Aavas Financiers | B47: NSE | C47: -24.5 | D47: 13 | E47: 18 | F47: =SUM(D47,E47) -> 31 | H47: Aavas Financiers | I47: NSE | J47: -723.5 | K47: 10 | L47: 18 | M47: =SUM(K47,L47) -> 28
...

Sheet MACD
A1: NBFC – General Sector | Backtesting Report
A2: Student: Vishv Jeet Singh Thakur | Institution: UPES | Strategy: MACD Intraday (5-Minute) | Time: 9:15 AM – 3:00 PM | FY 2025–26
A4: Q1 (Quarter 1): April 1, 2025 – June 30, 2025
A5: BUY / LONG CALL SIDE | H5: SELL / SHORT CALL SIDE
A6: Company Name | B6: Segment | C6: P&L (₹) | D6: Wins | E6: Losses | F6: Total Trades | H6: Company Name | I6: Segment | J6: P&L (₹) | K6: Wins | L6: Losses | M6: Total Trades
A7: Aavas Financiers | B7: NSE | C7: 809.6 | D7: 50 | E7: 76 | F7: =SUM(D7,E7) -> 126 | H7: Aavas Financiers | I7: NSE | J7: 1804.65 | K7: 54 | L7: 60 | M7: =SUM(K7,L7) -> 114
A8: Home First Finance Company India | B8: NSE | C8: 3345.5 | D8: 62 | E8: 74 | F8: =SUM(D8,E8) -> 136 | H8: Home First Finance Company India | I8: NSE | J8: -6938.1 | K8: 39 | L8: 94 | M8: =SUM(K8,L8) -> 133
A9: Five-Star Business Finance | B9: NSE | C9: 2020.2 | D9: 56 | E9: 67 | F9: =SUM(D9,E9) -> 123 | H9: Five-Star Business Finance | I9: NSE | J9: -1395.35 | K9: 46 | L9: 80 | M9: =SUM(K9,L9) -> 126
A10: IIFL Finance | B10: NSE | C10: -192.6 | D10: 51 | E10: 95 | F10: =SUM(D10,E10) -> 146 | H10: IIFL Finance | I10: NSE | J10: -473.1 | K10: 60 | L10: 82 | M10: =SUM(K10,L10) -> 142
A11: Manappuram Finance | B11: NSE | C11: 376.81 | D11: 45 | E11: 61 | F11: =SUM(D11,E11) -> 106 | H11: Manappuram Finance | I11: NSE | J11: -2851.93 | K11: 43 | L11: 60 | M11: =SUM(K11,L11) -> 103
A12: LIC Housing Finance | B12: NSE | C12: -602.25 | D12: 50 | E12: 68 | F12: =SUM(D12,E12) -> 118 | H12: LIC Housing Finance | I12: NSE | J12: -37.3 | K12: 42 | L12: 69 | M12: =SUM(K12,L12) -> 111
A13: Poonawalla Fincorp | B13: NSE | C13: 3334.5 | D13: 62 | E13: 65 | F13: =SUM(D13,E13) -> 127 | H13: Poonawalla Fincorp | I13: NSE | J13: -5659.85 | K13: 47 | L13: 95 | M13: =SUM(K13,L13) -> 142
A14: Mahindra & Mahindra Financial Services | B14: NSE | C14: -1160.05 | D14: 49 | E14: 66 | F14: =SUM(D14,E14) -> 115 | H14: Mahindra & Mahindra Financial Services | I14: NSE | J14: -3052.05 | K14: 42 | L14: 77 | M14: =SUM(K14,L14) -> 119
A15: Sundaram Finance | B15: NSE | C15: 1850.9 | D15: 55 | E15: 72 | F15: =SUM(D15,E15) -> 127 | H15: Sundaram Finance | I15: NSE | J15: -2818.15 | K15: 38 | L15: 68 | M15: =SUM(K15,L15) -> 106
A16: L&T Finance | B16: NSE | C16: 3578.7 | D16: 59 | E16: 64 | F16: =SUM(D16,E16) -> 123 | H16: L&T Finance | I16: NSE | J16: -5212.53 | K16: 47 | L16: 92 | M16: =SUM(K16,L16) -> 139
A17: Aditya Birla Capital | B17: NSE | C17: 2489.91 | D17: 57 | E17: 71 | F17: =SUM(D17,E17) -> 128 | H17: Aditya Birla Capital | I17: NSE | J17: -4872.53 | K17: 48 | L17: 94 | M17: =SUM(K17,L17) -> 142
A18: Muthoot Finance | B18: NSE | C18: 3058.5 | D18: 52 | E18: 58 | F18: =SUM(D18,E18) -> 110 | H18: Muthoot Finance | I18: NSE | J18: -3210.15 | K18: 43 | L18: 69 | M18: =SUM(K18,L18) -> 112
... A21: Bajaj Finance | B21: NSE | C21: 726.55 | D21: 46 | E21: 51 | F21: =SUM(D21,E21) -> 97 | H21: Bajaj Finance | I21: NSE | J21: -430.3 | K21: 45 | L21: 52 | M21: =SUM(K21,L21) -> 97
A22: TOTAL | C22: =SUM(C7:C21) -> 22095.27 | D22: =SUM(D7:D21) -> 810 | E22: =SUM(E7:E21) -> 1023 | F22: =SUM(F7:F21) -> 1833 | H22: TOTAL | J22: =SUM(J7:J21) -> -35779.89 | K22: =SUM(K7:K21) -> 693 | L22: =SUM(L7:L21) -> 1124 | M22: =SUM(M7:M21) -> 1817
A24: Q2 (Quarter 2): July 2, 2025 – September 30, 2025
A25: BUY / LONG CALL SIDE | H25: SELL / SHORT CALL SIDE
A26: Company Name | B26: Segment | C26: P&L (₹) | D26: Wins | E26: Losses | F26: Total Trades | H26: Company Name | I26: Segment | J26: P&L (₹) | K26: Wins | L26: Losses | M26: Total Trades
A27: Aavas Financiers | B27: NSE | C27: -3774.4 | D27: 44 | E27: 79 | F27: =SUM(D27,E27) -> 123 | H27: Aavas Financiers | I27: NSE | J27: 2869.15 | K27: 50 | L27: 50 | M27: =SUM(K27,L27) -> 100
A28: Home First Finance Company India | B28: NSE | C28: -3274.35 | D28: 47 | E28: 81 | F28: =SUM(D28,E28) -> 128 | H28: Home First Finance Company India | I28: NSE | J28: 1197.45 | K28: 50 | L28: 59 | M28: =SUM(K28,L28) -> 109
A29: Five-Star Business Finance | B29: NSE | C29: -2944.7 | D29: 52 | E29: 80 | F29: =SUM(D29,E29) -> 132 | H29: Five-Star Business Finance | I29: NSE | J29: 4325.75 | K29: 60 | L29: 50 | M29: =SUM(K29,L29) -> 110
A30: IIFL Finance | B30: NSE | C30: -1942.8 | D30: 49 | E30: 83 | F30: =SUM(D30,E30) -> 132 | H30: IIFL Finance | I30: NSE | J30: 1590.85 | K30: 51 | L30: 66 | M30: =SUM(K30,L30) -> 117
A31: Manappuram Finance | B31: NSE | C31: 236.1 | D31: 54 | E31: 67 | F31: =SUM(D31,E31) -> 121 | H31: Manappuram Finance | I31: NSE | J31: 2294.3 | K31: 54 | L31: 57 | M31: =SUM(K31,L31) -> 111
A32: LIC Housing Finance | B32: NSE | C32: -1725.45 | D32: 40 | E32: 52 | F32: =SUM(D32,E32) -> 92 | H32: LIC Housing Finance | I32: NSE | J32: 2287.7 | K32: 47 | L32: 40 | M32: =SUM(K32,L32) -> 87
A33: Poonawalla Fincorp | B33: NSE | C33: -965.1 | D33: 47 | E33: 85 | F33: =SUM(D33,E33) -> 132 | H33: Poonawalla Fincorp | I33: NSE | J33: 506.85 | K33: 54 | L33: 68 | M33: =SUM(K33,L33) -> 122
A34: Mahindra & Mahindra Financial Services | B34: NSE | C34: 2268.05 | D34: 50 | E34: 57 | F34: =SUM(D34,E34) -> 107 | H34: Mahindra & Mahindra Financial Services | I34: NSE | J34: -2230.8 | K34: 37 | L34: 69 | M34: =SUM(K34,L34) -> 106
A35: Sundaram Finance | B35: NSE | C35: -2673.2 | D35: 39 | E35: 73 | F35: =SUM(D35,E35) -> 112 | H35: Sundaram Finance | I35: NSE | J35: -614.85 | K35: 46 | L35: 63 | M35: =SUM(K35,L35) -> 109
A36: L&T Finance | B36: NSE | C36: 1065.92 | D36: 46 | E36: 65 | F36: =SUM(D36,E36) -> 111 | H36: L&T Finance | I36: NSE | J36: 1016.83 | K36: 54 | L36: 60 | M36: =SUM(K36,L36) -> 114
A37: Aditya Birla Capital | B37: NSE | C37: -2007.45 | D37: 40 | E37: 77 | F37: =SUM(D37,E37) -> 117 | H37: Aditya Birla Capital | I37: NSE | J37: 3396.35 | K37: 52 | L37: 55 | M37: =SUM(K37,L37) -> 107
A38: Muthoot Finance | B38: NSE | C38: 994.95 | D38: 53 | E38: 52 | F38: =SUM(D38,E38) -> 105 | H38: Muthoot Finance | I38: NSE | J38: -1717.7 | K38: 39 | L38: 56 | M38: =SUM(K38,L38) -> 95
... A41: Bajaj Finance | B41: NSE | C41: -1141.3 | D41: 40 | E41: 47 | F41: =SUM(D41,E41) -> 87 | H41: Bajaj Finance | I41: NSE | J41: -1018.45 | K41: 42 | L41: 55 | M41: =SUM(K41,L41) -> 97
A42: TOTAL | C42: =SUM(C27:C41) -> -16711.28 | D42: =SUM(D27:D41) -> 688 | E42: =SUM(E27:E41) -> 1021 | F42: =SUM(F27:F41) -> 1709 | H42: TOTAL | J42: =SUM(J27:J41) -> 15932.78 | K42: =SUM(K27:K41) -> 726 | L42: =SUM(L27:L41) -> 856 | M42: =SUM(M27:M41) -> 1582
A44: Q3 (Quarter 3): October 2, 2025 – December 31, 2025
A45: BUY / LONG CALL SIDE | H45: SELL / SHORT CALL SIDE
A46: Company Name | B46: Segment | C46: P&L (₹) | D46: Wins | E46: Losses | F46: Total Trades | H46: Company Name | I46: Segment | J46: P&L (₹) | K46: Wins | L46: Losses | M46: Total Trades
A47: Aavas Financiers | B47: NSE | C47: -587.85 | D47: 47 | E47: 62 | F47: =SUM(D47,E47) -> 109 | H47: Aavas Financiers | I47: NSE | J47: 828.05 | K47: 49 | L47: 61 | M47: =SUM(K47,L47) -> 110
...

Sheet RSI
A1: NBFC – General Sector | Backtesting Report
A2: Student: Vishv Jeet Singh Thakur | Institution: UPES | Strategy: RSI Intraday (5-Minute) | Time: 9:15 AM – 3:00 PM | FY 2025–26
A4: Q1 (Quarter 1): April 1, 2025 – June 30, 2025
A5: BUY / LONG CALL SIDE | H5: SELL / SHORT CALL SIDE
A6: Company Name | B6: Segment | C6: P&L (₹) | D6: Wins | E6: Losses | F6: Total Trades | H6: Company Name | I6: Segment | J6: P&L (₹) | K6: Wins | L6: Losses | M6: Total Trades
A7: Aavas Financiers | B7: NSE | C7: 1889.85 | D7: 34 | E7: 46 | F7: =SUM(D7,E7) -> 80 | H7: Aavas Financiers | I7: NSE | J7: -1504 | K7: 34 | L7: 51 | M7: =SUM(K7,L7) -> 85
A8: Home First Finance Company India | B8: NSE | C8: -119.2 | D8: 37 | E8: 60 | F8: =SUM(D8,E8) -> 97 | H8: Home First Finance Company India | I8: NSE | J8: -4611.35 | K8: 27 | L8: 66 | M8: =SUM(K8,L8) -> 93
A9: Five-Star Business Finance | B9: NSE | C9: -2.8 | D9: 35 | E9: 54 | F9: =SUM(D9,E9) -> 89 | H9: Five-Star Business Finance | I9: NSE | J9: -2228.05 | K9: 32 | L9: 62 | M9: =SUM(K9,L9) -> 94
A10: IIFL Finance | B10: NSE | C10: -645.1 | D10: 43 | E10: 65 | F10: =SUM(D10,E10) -> 108 | H10: IIFL Finance | I10: NSE | J10: -421.95 | K10: 42 | L10: 56 | M10: =SUM(K10,L10) -> 98
A11: Manappuram Finance | B11: NSE | C11: 1127.94 | D11: 37 | E11: 50 | F11: =SUM(D11,E11) -> 87 | H11: Manappuram Finance | I11: NSE | J11: -2324.82 | K11: 35 | L11: 46 | M11: =SUM(K11,L11) -> 81
A12: LIC Housing Finance | B12: NSE | C12: 1984.65 | D12: 37 | E12: 43 | F12: =SUM(D12,E12) -> 80 | H12: LIC Housing Finance | I12: NSE | J12: 1773.55 | K12: 37 | L12: 36 | M12: =SUM(K12,L12) -> 73
A13: Poonawalla Fincorp | B13: NSE | C13: -90.15 | D13: 41 | E13: 54 | F13: =SUM(D13,E13) -> 95 | H13: Poonawalla Fincorp | I13: NSE | J13: -1230.85 | K13: 30 | L13: 56 | M13: =SUM(K13,L13) -> 86
A14: Mahindra & Mahindra Financial Services | B14: NSE | C14: -618 | D14: 38 | E14: 46 | F14: =SUM(D14,E14) -> 84 | H14: Mahindra & Mahindra Financial Services | I14: NSE | J14: -1371.45 | K14: 37 | L14: 49 | M14: =SUM(K14,L14) -> 86
A15: Sundaram Finance | B15: NSE | C15: 2124.05 | D15: 40 | E15: 52 | F15: =SUM(D15,E15) -> 92 | H15: Sundaram Finance | I15: NSE | J15: -1464.7 | K15: 29 | L15: 53 | M15: =SUM(K15,L15) -> 82
A16: L&T Finance | B16: NSE | C16: 3538.72 | D16: 45 | E16: 48 | F16: =SUM(D16,E16) -> 93 | H16: L&T Finance | I16: NSE | J16: -921.96 | K16: 28 | L16: 52 | M16: =SUM(K16,L16) -> 80
A17: Aditya Birla Capital | B17: NSE | C17: 3090.38 | D17: 45 | E17: 50 | F17: =SUM(D17,E17) -> 95 | H17: Aditya Birla Capital | I17: NSE | J17: -631.31 | K17: 34 | L17: 53 | M17: =SUM(K17,L17) -> 87
A18: Muthoot Finance | B18: NSE | C18: 1923.15 | D18: 39 | E18: 40 | F18: =SUM(D18,E18) -> 79 | H18: Muthoot Finance | I18: NSE | J18: -2474.85 | K18: 27 | L18: 50 | M18: =SUM(K18,L18) -> 77
... A21: Bajaj Finance | B21: NSE | C21: 1311.9 | D21: 38 | E21: 36 | F21: =SUM(D21,E21) -> 74 | H21: Bajaj Finance | I21: NSE | J21: -375.05 | K21: 36 | L21: 42 | M21: =SUM(K21,L21) -> 78
A22: TOTAL | C22: =SUM(C7:C21) -> 17070.79 | D22: =SUM(D7:D21) -> 589 | E22: =SUM(E7:E21) -> 747 | F22: =SUM(F7:F21) -> 1336 | H22: TOTAL | J22: =SUM(J7:J21) -> -15632.39 | K22: =SUM(K7:K21) -> 500 | L22: =SUM(L7:L21) -> 753 | M22: =SUM(M7:M21) -> 1253
A24: Q2 (Quarter 2): July 2, 2025 – September 30, 2025
A25: BUY / LONG CALL SIDE | H25: SELL / SHORT CALL SIDE
A26: Company Name | B26: Segment | C26: P&L (₹) | D26: Wins | E26: Losses | F26: Total Trades | H26: Company Name | I26: Segment | J26: P&L (₹) | K26: Wins | L26: Losses | M26: Total Trades
A27: Aavas Financiers | B27: NSE | C27: -1583.9 | D27: 32 | E27: 53 | F27: =SUM(D27,E27) -> 85 | H27: Aavas Financiers | I27: NSE | J27: 3081.95 | K27: 40 | L27: 38 | M27: =SUM(K27,L27) -> 78
A28: Home First Finance Company India | B28: NSE | C28: 769.35 | D28: 41 | E28: 45 | F28: =SUM(D28,E28) -> 86 | H28: Home First Finance Company India | I28: NSE | J28: 1613.65 | K28: 39 | L28: 49 | M28: =SUM(K28,L28) -> 88
A29: Five-Star Business Finance | B29: NSE | C29: -2192.2 | D29: 31 | E29: 60 | F29: =SUM(D29,E29) -> 91 | H29: Five-Star Business Finance | I29: NSE | J29: 13.3 | K29: 40 | L29: 52 | M29: =SUM(K29,L29) -> 92
A30: IIFL Finance | B30: NSE | C30: 1627.55 | D30: 34 | E30: 43 | F30: =SUM(D30,E30) -> 77 | H30: IIFL Finance | I30: NSE | J30: 3230.2 | K30: 40 | L30: 43 | M30: =SUM(K30,L30) -> 83
A31: Manappuram Finance | B31: NSE | C31: -1565.35 | D31: 33 | E31: 56 | F31: =SUM(D31,E31) -> 89 | H31: Manappuram Finance | I31: NSE | J31: 3471.8 | K31: 39 | L31: 37 | M31: =SUM(K31,L31) -> 76
A32: LIC Housing Finance | B32: NSE | C32: -1193.85 | D32: 35 | E32: 40 | F32: =SUM(D32,E32) -> 75 | H32: LIC Housing Finance | I32: NSE | J32: 2000.55 | K32: 48 | L32: 30 | M32: =SUM(K32,L32) -> 78
A33: Poonawalla Fincorp | B33: NSE | C33: 1236.95 | D33: 42 | E33: 49 | F33: =SUM(D33,E33) -> 91 | H33: Poonawalla Fincorp | I33: NSE | J33: 184.9 | K33: 39 | L33: 48 | M33: =SUM(K33,L33) -> 87
A34: Mahindra & Mahindra Financial Services | B34: NSE | C34: 2716.6 | D34: 41 | E34: 35 | F34: =SUM(D34,E34) -> 76 | H34: Mahindra & Mahindra Financial Services | I34: NSE | J34: 15.35 | K34: 35 | L34: 41 | M34: =SUM(K34,L34) -> 76
A35: Sundaram Finance | B35: NSE | C35: 2141.2 | D35: 35 | E35: 34 | F35: =SUM(D35,E35) -> 69 | H35: Sundaram Finance | I35: NSE | J35: 3626.85 | K35: 42 | L35: 38 | M35: =SUM(K35,L35) -> 80
A36: L&T Finance | B36: NSE | C36: 1292.68 | D36: 39 | E36: 54 | F36: =SUM(D36,E36) -> 93 | H36: L&T Finance | I36: NSE | J36: -95.73 | K36: 38 | L36: 41 | M36: =SUM(K36,L36) -> 79
A37: Aditya Birla Capital | B37: NSE | C37: -1508.6 | D37: 37 | E37: 50 | F37: =SUM(D37,E37) -> 87 | H37: Aditya Birla Capital | I37: NSE | J37: 2539.95 | K37: 44 | L37: 37 | M37: =SUM(K37,L37) -> 81
A38: Muthoot Finance | B38: NSE | C38: 634.35 | D38: 38 | E38: 41 | F38: =SUM(D38,E38) -> 79 | H38: Muthoot Finance | I38: NSE | J38: 552.5 | K38: 35 | L38: 37 | M38: =SUM(K38,L38) -> 72
... A41: Bajaj Finance | B41: NSE | C41: -1082.3 | D41: 36 | E41: 36 | F41: =SUM(D41,E41) -> 72 | H41: Bajaj Finance | I41: NSE | J41: -523.8 | K41: 34 | L41: 39 | M41: =SUM(K41,L41) -> 73
A42: TOTAL | C42: =SUM(C27:C41) -> -261.87 | D42: =SUM(D27:D41) -> 544 | E42: =SUM(E27:E41) -> 691 | F42: =SUM(F27:F41) -> 1235 | H42: TOTAL | J42: =SUM(J27:J41) -> 22303.82 | K42: =SUM(K27:K41) -> 588 | L42: =SUM(L27:L41) -> 609 | M42: =SUM(M27:M41) -> 1197
A44: Q3 (Quarter 3): October 2, 2025 – December 31, 2025
A45: BUY / LONG CALL SIDE | H45: SELL / SHORT CALL SIDE
A46: Company Name | B46: Segment | C46: P&L (₹) | D46: Wins | E46: Losses | F46: Total Trades | H46: Company Name | I46: Segment | J46: P&L (₹) | K46: Wins | L46: Losses | M46: Total Trades
A47: Aavas Financiers | B47: NSE | C47: 1249.6 | D47: 32 | E47: 46 | F47: =SUM(D47,E47) -> 78 | H47: Aavas Financiers | I47: NSE | J47: -575.75 | K47: 32 | L47: 49 | M47: =SUM(K47,L47) -> 81
...

Sheet Stochastic RSI
A1: NBFC – General Sector | Backtesting Report
A2: Student: Vishv Jeet Singh Thakur | Institution: UPES | Strategy: Stochastic RSI Intraday (5-Minute) | Time: 9:15 AM – 3:00 PM | FY 2025–26
A4: Q1 (Quarter 1): April 1, 2025 – June 30, 2025
A5: BUY / LONG CALL SIDE | H5: SELL / SHORT CALL SIDE
A6: Company Name | B6: Segment | C6: P&L (₹) | D6: Wins | E6: Losses | F6: Total Trades | H6: Company Name | I6: Segment | J6: P&L (₹) | K6: Wins | L6: Losses | M6: Total Trades
A7: Aavas Financiers | B7: NSE | C7: -2833.8 | D7: 41 | E7: 81 | F7: =SUM(D7,E7) -> 122 | H7: Aavas Financiers | I7: NSE | J7: -3033 | K7: 62 | L7: 112 | M7: =SUM(K7,L7) -> 174
A8: Home First Finance Company India | B8: NSE | C8: 5512.55 | D8: 62 | E8: 64 | F8: =SUM(D8,E8) -> 126 | H8: Home First Finance Company India | I8: NSE | J8: -10245.95 | K8: 52 | L8: 133 | M8: =SUM(K8,L8) -> 185
A9: Five-Star Business Finance | B9: NSE | C9: 2362.45 | D9: 55 | E9: 68 | F9: =SUM(D9,E9) -> 123 | H9: Five-Star Business Finance | I9: NSE | J9: 676.8 | K9: 59 | L9: 99 | M9: =SUM(K9,L9) -> 158
A10: IIFL Finance | B10: NSE | C10: -537.9 | D10: 54 | E10: 91 | F10: =SUM(D10,E10) -> 145 | H10: IIFL Finance | I10: NSE | J10: -2312.45 | K10: 73 | L10: 115 | M10: =SUM(K10,L10) -> 188
A11: Manappuram Finance | B11: NSE | C11: 3757.27 | D11: 51 | E11: 45 | F11: =SUM(D11,E11) -> 96 | H11: Manappuram Finance | I11: NSE | J11: -2570.57 | K11: 59 | L11: 70 | M11: =SUM(K11,L11) -> 129
A12: LIC Housing Finance | B12: NSE | C12: -1385.65 | D12: 44 | E12: 68 | F12: =SUM(D12,E12) -> 112 | H12: LIC Housing Finance | I12: NSE | J12: 1108.15 | K12: 53 | L12: 77 | M12: =SUM(K12,L12) -> 130
A13: Poonawalla Fincorp | B13: NSE | C13: 1763.65 | D13: 54 | E13: 68 | F13: =SUM(D13,E13) -> 122 | H13: Poonawalla Fincorp | I13: NSE | J13: -7776.15 | K13: 51 | L13: 119 | M13: =SUM(K13,L13) -> 170
A14: Mahindra & Mahindra Financial Services | B14: NSE | C14: -427.6 | D14: 53 | E14: 57 | F14: =SUM(D14,E14) -> 110 | H14: Mahindra & Mahindra Financial Services | I14: NSE | J14: -1705 | K14: 55 | L14: 82 | M14: =SUM(K14,L14) -> 137
A15: Sundaram Finance | B15: NSE | C15: 3557.8 | D15: 52 | E15: 62 | F15: =SUM(D15,E15) -> 114 | H15: Sundaram Finance | I15: NSE | J15: -3025.95 | K15: 47 | L15: 87 | M15: =SUM(K15,L15) -> 134
A16: L&T Finance | B16: NSE | C16: 3967.62 | D16: 59 | E16: 62 | F16: =SUM(D16,E16) -> 121 | H16: L&T Finance | I16: NSE | J16: -5926.86 | K16: 58 | L16: 111 | M16: =SUM(K16,L16) -> 169
A17: Aditya Birla Capital | B17: NSE | C17: 1707.33 | D17: 53 | E17: 72 | F17: =SUM(D17,E17) -> 125 | H17: Aditya Birla Capital | I17: NSE | J17: -5569.87 | K17: 49 | L17: 108 | M17: =SUM(K17,L17) -> 157
A18: Muthoot Finance | B18: NSE | C18: 1411.05 | D18: 48 | E18: 60 | F18: =SUM(D18,E18) -> 108 | H18: Muthoot Finance | I18: NSE | J18: -3860.7 | K18: 51 | L18: 90 | M18: =SUM(K18,L18) -> 141
... A21: Bajaj Finance | B21: NSE | C21: 224.35 | D21: 51 | E21: 53 | F21: =SUM(D21,E21) -> 104 | H21: Bajaj Finance | I21: NSE | J21: -2597.9 | K21: 53 | L21: 70 | M21: =SUM(K21,L21) -> 123
A22: TOTAL | C22: =SUM(C7:C21) -> 21505.02 | D22: =SUM(D7:D21) -> 780 | E22: =SUM(E7:E21) -> 982 | F22: =SUM(F7:F21) -> 1762 | H22: TOTAL | J22: =SUM(J7:J21) -> -48716.45 | K22: =SUM(K7:K21) -> 838 | L22: =SUM(L7:L21) -> 1453 | M22: =SUM(M7:M21) -> 2291
A24: Q2 (Quarter 2): July 2, 2025 – September 30, 2025
A25: BUY / LONG CALL SIDE | H25: SELL / SHORT CALL SIDE
A26: Company Name | B26: Segment | C26: P&L (₹) | D26: Wins | E26: Losses | F26: Total Trades | H26: Company Name | I26: Segment | J26: P&L (₹) | K26: Wins | L26: Losses | M26: Total Trades
A27: Aavas Financiers | B27: NSE | C27: -913.9 | D27: 49 | E27: 71 | F27: =SUM(D27,E27) -> 120 | H27: Aavas Financiers | I27: NSE | J27: 4247.05 | K27: 64 | L27: 67 | M27: =SUM(K27,L27) -> 131
A28: Home First Finance Company India | B28: NSE | C28: -541.3 | D28: 44 | E28: 65 | F28: =SUM(D28,E28) -> 109 | H28: Home First Finance Company India | I28: NSE | J28: 1652.95 | K28: 62 | L28: 83 | M28: =SUM(K28,L28) -> 145
A29: Five-Star Business Finance | B29: NSE | C29: -2954.9 | D29: 43 | E29: 72 | F29: =SUM(D29,E29) -> 115 | H29: Five-Star Business Finance | I29: NSE | J29: 6157.5 | K29: 74 | L29: 59 | M29: =SUM(K29,L29) -> 133
A30: IIFL Finance | B30: NSE | C30: -1262.3 | D30: 46 | E30: 72 | F30: =SUM(D30,E30) -> 118 | H30: IIFL Finance | I30: NSE | J30: 77.6 | K30: 68 | L30: 96 | M30: =SUM(K30,L30) -> 164
A31: Manappuram Finance | B31: NSE | C31: -1160.05 | D31: 55 | E31: 68 | F31: =SUM(D31,E31) -> 123 | H31: Manappuram Finance | I31: NSE | J31: 4230.95 | K31: 65 | L31: 73 | M31: =SUM(K31,L31) -> 138
A32: LIC Housing Finance | B32: NSE | C32: -2773 | D32: 39 | E32: 56 | F32: =SUM(D32,E32) -> 95 | H32: LIC Housing Finance | I32: NSE | J32: 2285.55 | K32: 53 | L32: 50 | M32: =SUM(K32,L32) -> 103
A33: Poonawalla Fincorp | B33: NSE | C33: -88.1 | D33: 46 | E33: 71 | F33: =SUM(D33,E33) -> 117 | H33: Poonawalla Fincorp | I33: NSE | J33: -468.55 | K33: 69 | L33: 92 | M33: =SUM(K33,L33) -> 161
A34: Mahindra & Mahindra Financial Services | B34: NSE | C34: 1406.5 | D34: 44 | E34: 53 | F34: =SUM(D34,E34) -> 97 | H34: Mahindra & Mahindra Financial Services | I34: NSE | J34: -2578.25 | K34: 48 | L34: 72 | M34: =SUM(K34,L34) -> 120
A35: Sundaram Finance | B35: NSE | C35: -1121.9 | D35: 41 | E35: 63 | F35: =SUM(D35,E35) -> 104 | H35: Sundaram Finance | I35: NSE | J35: 1432.6 | K35: 54 | L35: 72 | M35: =SUM(K35,L35) -> 126
A36: L&T Finance | B36: NSE | C36: 420.35 | D36: 43 | E36: 68 | F36: =SUM(D36,E36) -> 111 | H36: L&T Finance | I36: NSE | J36: -195.65 | K36: 66 | L36: 74 | M36: =SUM(K36,L36) -> 140
A37: Aditya Birla Capital | B37: NSE | C37: -3264 | D37: 41 | E37: 73 | F37: =SUM(D37,E37) -> 114 | H37: Aditya Birla Capital | I37: NSE | J37: 3581.2 | K37: 64 | L37: 70 | M37: =SUM(K37,L37) -> 134
A38: Muthoot Finance | B38: NSE | C38: 581.95 | D38: 43 | E38: 46 | F38: =SUM(D38,E38) -> 89 | H38: Muthoot Finance | I38: NSE | J38: -874.9 | K38: 45 | L38: 55 | M38: =SUM(K38,L38) -> 100
... A41: Bajaj Finance | B41: NSE | C41: 1307.8 | D41: 45 | E41: 45 | F41: =SUM(D41,E41) -> 90 | H41: Bajaj Finance | I41: NSE | J41: 76.95 | K41: 44 | L41: 57 | M41: =SUM(K41,L41) -> 101
A42: TOTAL | C42: =SUM(C27:C41) -> -9907.2 | D42: =SUM(D27:D41) -> 663 | E42: =SUM(E27:E41) -> 942 | F42: =SUM(F27:F41) -> 1605 | H42: TOTAL | J42: =SUM(J27:J41) -> 23159.55 | K42: =SUM(K27:K41) -> 883 | L42: =SUM(L27:L41) -> 1043 | M42: =SUM(M27:M41) -> 1926
A44: Q3 (Quarter 3): October 2, 2025 – December 31, 2025
A45: BUY / LONG CALL SIDE | H45: SELL / SHORT CALL SIDE
A46: Company Name | B46: Segment | C46: P&L (₹) | D46: Wins | E46: Losses | F46: Total Trades | H46: Company Name | I46: Segment | J46: P&L (₹) | K46: Wins | L46: Losses | M46: Total Trades
A47: Aavas Financiers | B47: NSE | C47: -530 | D47: 42 | E47: 66 | F47: =SUM(D47,E47) -> 108 | H47: Aavas Financiers | I47: NSE | J47: 2023.55 | K47: 59 | L47: 67 | M47: =SUM(K47,L47) -> 126
...

Sheet BB
A1: NBFC – General Sector | Backtesting Report
A2: Student: Vishv Jeet Singh Thakur | Institution: UPES | Strategy: Bollinger Bands (BB) Intraday (5-Minute) | Time: 9:15 AM – 3:00 PM | FY 2025–26
A4: Q1 (Quarter 1): April 1, 2025 – June 30, 2025
A5: BUY / LONG CALL SIDE | H5: SELL / SHORT CALL SIDE
A6: Company Name | B6: Segment | C6: P&L (₹) | D6: Wins | E6: Losses | F6: Total Trades | H6: Company Name | I6: Segment | J6: P&L (₹) | K6: Wins | L6: Losses | M6: Total Trades
A7: Aavas Financiers | B7: NSE | C7: 1755.85 | D7: 28 | E7: 38 | F7: =SUM(D7,E7) -> 66 | H7: Aavas Financiers | I7: NSE | J7: 751.3 | K7: 32 | L7: 42 | M7: =SUM(K7,L7) -> 74
A8: Home First Finance Company India | B8: NSE | C8: 1732.7 | D8: 36 | E8: 46 | F8: =SUM(D8,E8) -> 82 | H8: Home First Finance Company India | I8: NSE | J8: -3541.55 | K8: 22 | L8: 52 | M8: =SUM(K8,L8) -> 74
A9: Five-Star Business Finance | B9: NSE | C9: 1459.55 | D9: 36 | E9: 49 | F9: =SUM(D9,E9) -> 85 | H9: Five-Star Business Finance | I9: NSE | J9: 619.3 | K9: 28 | L9: 46 | M9: =SUM(K9,L9) -> 74
A10: IIFL Finance | B10: NSE | C10: 2751.4 | D10: 40 | E10: 46 | F10: =SUM(D10,E10) -> 86 | H10: IIFL Finance | I10: NSE | J10: -203.75 | K10: 36 | L10: 44 | M10: =SUM(K10,L10) -> 80
A11: Manappuram Finance | B11: NSE | C11: -1127.41 | D11: 31 | E11: 45 | F11: =SUM(D11,E11) -> 76 | H11: Manappuram Finance | I11: NSE | J11: -1306.06 | K11: 27 | L11: 38 | M11: =SUM(K11,L11) -> 65
A12: LIC Housing Finance | B12: NSE | C12: 1621.6 | D12: 32 | E12: 36 | F12: =SUM(D12,E12) -> 68 | H12: LIC Housing Finance | I12: NSE | J12: 3024.45 | K12: 35 | L12: 34 | M12: =SUM(K12,L12) -> 69
A13: Poonawalla Fincorp | B13: NSE | C13: -668.9 | D13: 35 | E13: 48 | F13: =SUM(D13,E13) -> 83 | H13: Poonawalla Fincorp | I13: NSE | J13: -2832.1 | K13: 18 | L13: 49 | M13: =SUM(K13,L13) -> 67
A14: Mahindra & Mahindra Financial Services | B14: NSE | C14: -1200.05 | D14: 29 | E14: 37 | F14: =SUM(D14,E14) -> 66 | H14: Mahindra & Mahindra Financial Services | I14: NSE | J14: 289.5 | K14: 29 | L14: 44 | M14: =SUM(K14,L14) -> 73
A15: Sundaram Finance | B15: NSE | C15: 2167.5 | D15: 34 | E15: 41 | F15: =SUM(D15,E15) -> 75 | H15: Sundaram Finance | I15: NSE | J15: -2212.25 | K15: 21 | L15: 43 | M15: =SUM(K15,L15) -> 64
A16: L&T Finance | B16: NSE | C16: 3268.17 | D16: 41 | E16: 46 | F16: =SUM(D16,E16) -> 87 | H16: L&T Finance | I16: NSE | J16: -888.8 | K16: 24 | L16: 37 | M16: =SUM(K16,L16) -> 61
A17: Aditya Birla Capital | B17: NSE | C17: 1286.28 | D17: 33 | E17: 48 | F17: =SUM(D17,E17) -> 81 | H17: Aditya Birla Capital | I17: NSE | J17: -2066.47 | K17: 28 | L17: 46 | M17: =SUM(K17,L17) -> 74
A18: Muthoot Finance | B18: NSE | C18: 2877.35 | D18: 39 | E18: 39 | F18: =SUM(D18,E18) -> 78 | H18: Muthoot Finance | I18: NSE | J18: -103.55 | K18: 28 | L18: 39 | M18: =SUM(K18,L18) -> 67
... A21: Bajaj Finance | B21: NSE | C21: 1176.9 | D21: 38 | E21: 30 | F21: =SUM(D21,E21) -> 68 | H21: Bajaj Finance | I21: NSE | J21: -1064.7 | K21: 28 | L21: 37 | M21: =SUM(K21,L21) -> 65
A22: TOTAL | C22: =SUM(C7:C21) -> 20613.69 | D22: =SUM(D7:D21) -> 522 | E22: =SUM(E7:E21) -> 631 | F22: =SUM(F7:F21) -> 1153 | H22: TOTAL | J22: =SUM(J7:J21) -> -10593.63 | K22: =SUM(K7:K21) -> 410 | L22: =SUM(L7:L21) -> 633 | M22: =SUM(M7:M21) -> 1043
A24: Q2 (Quarter 2): July 2, 2025 – September 30, 2025
A25: BUY / LONG CALL SIDE | H25: SELL / SHORT CALL SIDE
A26: Company Name | B26: Segment | C26: P&L (₹) | D26: Wins | E26: Losses | F26: Total Trades | H26: Company Name | I26: Segment | J26: P&L (₹) | K26: Wins | L26: Losses | M26: Total Trades
A27: Aavas Financiers | B27: NSE | C27: -168.2 | D27: 30 | E27: 40 | F27: =SUM(D27,E27) -> 70 | H27: Aavas Financiers | I27: NSE | J27: -106.3 | K27: 30 | L27: 46 | M27: =SUM(K27,L27) -> 76
A28: Home First Finance Company India | B28: NSE | C28: 516.1 | D28: 35 | E28: 42 | F28: =SUM(D28,E28) -> 77 | H28: Home First Finance Company India | I28: NSE | J28: 2493.9 | K28: 30 | L28: 34 | M28: =SUM(K28,L28) -> 64
A29: Five-Star Business Finance | B29: NSE | C29: 202.75 | D29: 31 | E29: 38 | F29: =SUM(D29,E29) -> 69 | H29: Five-Star Business Finance | I29: NSE | J29: 2941.45 | K29: 36 | L29: 35 | M29: =SUM(K29,L29) -> 71
A30: IIFL Finance | B30: NSE | C30: 3013.45 | D30: 34 | E30: 34 | F30: =SUM(D30,E30) -> 68 | H30: IIFL Finance | I30: NSE | J30: 2615.25 | K30: 37 | L30: 36 | M30: =SUM(K30,L30) -> 73
A31: Manappuram Finance | B31: NSE | C31: -515.95 | D31: 29 | E31: 42 | F31: =SUM(D31,E31) -> 71 | H31: Manappuram Finance | I31: NSE | J31: 1107.7 | K31: 35 | L31: 39 | M31: =SUM(K31,L31) -> 74
A32: LIC Housing Finance | B32: NSE | C32: -2147.05 | D32: 23 | E32: 43 | F32: =SUM(D32,E32) -> 66 | H32: LIC Housing Finance | I32: NSE | J32: 773.9 | K32: 35 | L32: 29 | M32: =SUM(K32,L32) -> 64
A33: Poonawalla Fincorp | B33: NSE | C33: 1863.15 | D33: 37 | E33: 43 | F33: =SUM(D33,E33) -> 80 | H33: Poonawalla Fincorp | I33: NSE | J33: 399.15 | K33: 31 | L33: 38 | M33: =SUM(K33,L33) -> 69
A34: Mahindra & Mahindra Financial Services | B34: NSE | C34: 2147.5 | D34: 35 | E34: 37 | F34: =SUM(D34,E34) -> 72 | H34: Mahindra & Mahindra Financial Services | I34: NSE | J34: -1654.1 | K34: 27 | L34: 41 | M34: =SUM(K34,L34) -> 68
A35: Sundaram Finance | B35: NSE | C35: 1007.8 | D35: 26 | E35: 28 | F35: =SUM(D35,E35) -> 54 | H35: Sundaram Finance | I35: NSE | J35: 1642.7 | K35: 30 | L35: 37 | M35: =SUM(K35,L35) -> 67
A36: L&T Finance | B36: NSE | C36: 366.94 | D36: 32 | E36: 48 | F36: =SUM(D36,E36) -> 80 | H36: L&T Finance | I36: NSE | J36: -386.24 | K36: 34 | L36: 40 | M36: =SUM(K36,L36) -> 74
A37: Aditya Birla Capital | B37: NSE | C37: 983.35 | D37: 30 | E37: 36 | F37: =SUM(D37,E37) -> 66 | H37: Aditya Birla Capital | I37: NSE | J37: -59.35 | K37: 38 | L37: 41 | M37: =SUM(K37,L37) -> 79
A38: Muthoot Finance | B38: NSE | C38: -204.35 | D38: 33 | E38: 33 | F38: =SUM(D38,E38) -> 66 | H38: Muthoot Finance | I38: NSE | J38: -1822.1 | K38: 24 | L38: 36 | M38: =SUM(K38,L38) -> 60
... A41: Bajaj Finance | B41: NSE | C41: 1656.9 | D41: 33 | E41: 30 | F41: =SUM(D41,E41) -> 63 | H41: Bajaj Finance | I41: NSE | J41: 636.2 | K41: 28 | L41: 27 | M41: =SUM(K41,L41) -> 55
A42: TOTAL | C42: =SUM(C27:C41) -> 8725.14 | D42: =SUM(D27:D41) -> 468 | E42: =SUM(E27:E41) -> 572 | F42: =SUM(F27:F41) -> 1040 | H42: TOTAL | J42: =SUM(J27:J41) -> 10736.56 | K42: =SUM(K27:K41) -> 478 | L42: =SUM(L27:L41) -> 551 | M42: =SUM(M27:M41) -> 1029
A44: Q3 (Quarter 3): October 2, 2025 – December 31, 2025
A45: BUY / LONG CALL SIDE | H45: SELL / SHORT CALL SIDE
A46: Company Name | B46: Segment | C46: P&L (₹) | D46: Wins | E46: Losses | F46: Total Trades | H46: Company Name | I46: Segment | J46: P&L (₹) | K46: Wins | L46: Losses | M46: Total Trades
A47: Aavas Financiers | B47: NSE | C47: 321.6 | D47: 25 | E47: 41 | F47: =SUM(D47,E47) -> 66 | H47: Aavas Financiers | I47: NSE | J47: 674.3 | K47: 24 | L47: 36 | M47: =SUM(K47,L47) -> 60
...

Sheet AO
A1: NBFC – General Sector | Backtesting Report
A2: Student: Vishv Jeet Singh Thakur | Institution: UPES | Strategy: Awesome Oscillator (AO) Intraday (5-Minute) | Time: 9:15 AM – 3:00 PM | FY 2025–26
A4: Q1 (Quarter 1): April 1, 2025 – June 30, 2025
A5: BUY / LONG CALL SIDE | H5: SELL / SHORT CALL SIDE
A6: Company Name | B6: Segment | C6: P&L (₹) | D6: Wins | E6: Losses | F6: Total Trades | H6: Company Name | I6: Segment | J6: P&L (₹) | K6: Wins | L6: Losses | M6: Total Trades
A7: Aavas Financiers | B7: NSE | C7: 1677.55 | D7: 28 | E7: 33 | F7: =SUM(D7,E7) -> 61 | H7: Aavas Financiers | I7: NSE | J7: 1357.35 | K7: 30 | L7: 34 | M7: =SUM(K7,L7) -> 64
A8: Home First Finance Company India | B8: NSE | C8: 2181 | D8: 33 | E8: 36 | F8: =SUM(D8,E8) -> 69 | H8: Home First Finance Company India | I8: NSE | J8: -2502.85 | K8: 22 | L8: 43 | M8: =SUM(K8,L8) -> 65
A9: Five-Star Business Finance | B9: NSE | C9: 1613.95 | D9: 31 | E9: 34 | F9: =SUM(D9,E9) -> 65 | H9: Five-Star Business Finance | I9: NSE | J9: -2432.45 | K9: 21 | L9: 53 | M9: =SUM(K9,L9) -> 74
A10: IIFL Finance | B10: NSE | C10: -508.9 | D10: 27 | E10: 46 | F10: =SUM(D10,E10) -> 73 | H10: IIFL Finance | I10: NSE | J10: 1132.8 | K10: 37 | L10: 34 | M10: =SUM(K10,L10) -> 71
A11: Manappuram Finance | B11: NSE | C11: 1256.31 | D11: 31 | E11: 39 | F11: =SUM(D11,E11) -> 70 | H11: Manappuram Finance | I11: NSE | J11: -1329.52 | K11: 29 | L11: 39 | M11: =SUM(K11,L11) -> 68
A12: LIC Housing Finance | B12: NSE | C12: 1916.95 | D12: 32 | E12: 31 | F12: =SUM(D12,E12) -> 63 | H12: LIC Housing Finance | I12: NSE | J12: 926.5 | K12: 29 | L12: 33 | M12: =SUM(K12,L12) -> 62
A13: Poonawalla Fincorp | B13: NSE | C13: -2812.7 | D13: 23 | E13: 47 | F13: =SUM(D13,E13) -> 70 | H13: Poonawalla Fincorp | I13: NSE | J13: -1461.4 | K13: 23 | L13: 45 | M13: =SUM(K13,L13) -> 68
A14: Mahindra & Mahindra Financial Services | B14: NSE | C14: 755.25 | D14: 29 | E14: 34 | F14: =SUM(D14,E14) -> 63 | H14: Mahindra & Mahindra Financial Services | I14: NSE | J14: -454.1 | K14: 31 | L14: 38 | M14: =SUM(K14,L14) -> 69
A15: Sundaram Finance | B15: NSE | C15: 1724.6 | D15: 30 | E15: 35 | F15: =SUM(D15,E15) -> 65 | H15: Sundaram Finance | I15: NSE | J15: -1195.05 | K15: 28 | L15: 42 | M15: =SUM(K15,L15) -> 70
A16: L&T Finance | B16: NSE | C16: 2194.05 | D16: 30 | E16: 31 | F16: =SUM(D16,E16) -> 61 | H16: L&T Finance | I16: NSE | J16: 290.56 | K16: 30 | L16: 37 | M16: =SUM(K16,L16) -> 67
A17: Aditya Birla Capital | B17: NSE | C17: 1798.27 | D17: 31 | E17: 38 | F17: =SUM(D17,E17) -> 69 | H17: Aditya Birla Capital | I17: NSE | J17: -986 | K17: 28 | L17: 38 | M17: =SUM(K17,L17) -> 66
A18: Muthoot Finance | B18: NSE | C18: 3135.25 | D18: 37 | E18: 20 | F18: =SUM(D18,E18) -> 57 | H18: Muthoot Finance | I18: NSE | J18: -1272.65 | K18: 28 | L18: 37 | M18: =SUM(K18,L18) -> 65
... A21: Bajaj Finance | B21: NSE | C21: 1618.95 | D21: 33 | E21: 22 | F21: =SUM(D21,E21) -> 55 | H21: Bajaj Finance | I21: NSE | J21: -396 | K21: 27 | L21: 30 | M21: =SUM(K21,L21) -> 57
A22: TOTAL | C22: =SUM(C7:C21) -> 18142.83 | D22: =SUM(D7:D21) -> 459 | E22: =SUM(E7:E21) -> 513 | F22: =SUM(F7:F21) -> 972 | H22: TOTAL | J22: =SUM(J7:J21) -> -9698.71 | K22: =SUM(K7:K21) -> 414 | L22: =SUM(L7:L21) -> 582 | M22: =SUM(M7:M21) -> 996
A24: Q2 (Quarter 2): July 2, 2025 – September 30, 2025
A25: BUY / LONG CALL SIDE | H25: SELL / SHORT CALL SIDE
A26: Company Name | B26: Segment | C26: P&L (₹) | D26: Wins | E26: Losses | F26: Total Trades | H26: Company Name | I26: Segment | J26: P&L (₹) | K26: Wins | L26: Losses | M26: Total Trades
A27: Aavas Financiers | B27: NSE | C27: 1005.85 | D27: 32 | E27: 36 | F27: =SUM(D27,E27) -> 68 | H27: Aavas Financiers | I27: NSE | J27: 2684.65 | K27: 32 | L27: 28 | M27: =SUM(K27,L27) -> 60
A28: Home First Finance Company India | B28: NSE | C28: -777.2 | D28: 30 | E28: 38 | F28: =SUM(D28,E28) -> 68 | H28: Home First Finance Company India | I28: NSE | J28: 109.4 | K28: 25 | L28: 36 | M28: =SUM(K28,L28) -> 61
A29: Five-Star Business Finance | B29: NSE | C29: -1684.95 | D29: 29 | E29: 48 | F29: =SUM(D29,E29) -> 77 | H29: Five-Star Business Finance | I29: NSE | J29: 1536.8 | K29: 38 | L29: 40 | M29: =SUM(K29,L29) -> 78
A30: IIFL Finance | B30: NSE | C30: -226.35 | D30: 29 | E30: 40 | F30: =SUM(D30,E30) -> 69 | H30: IIFL Finance | I30: NSE | J30: 1668.05 | K30: 33 | L30: 37 | M30: =SUM(K30,L30) -> 70
A31: Manappuram Finance | B31: NSE | C31: -3222 | D31: 27 | E31: 52 | F31: =SUM(D31,E31) -> 79 | H31: Manappuram Finance | I31: NSE | J31: 2918.35 | K31: 33 | L31: 32 | M31: =SUM(K31,L31) -> 65
A32: LIC Housing Finance | B32: NSE | C32: -3199.35 | D32: 22 | E32: 41 | F32: =SUM(D32,E32) -> 63 | H32: LIC Housing Finance | I32: NSE | J32: 2486.95 | K32: 40 | L32: 22 | M32: =SUM(K32,L32) -> 62
A33: Poonawalla Fincorp | B33: NSE | C33: 977.65 | D33: 30 | E33: 39 | F33: =SUM(D33,E33) -> 69 | H33: Poonawalla Fincorp | I33: NSE | J33: 1533.95 | K33: 33 | L33: 27 | M33: =SUM(K33,L33) -> 60
A34: Mahindra & Mahindra Financial Services | B34: NSE | C34: 2127.15 | D34: 31 | E34: 33 | F34: =SUM(D34,E34) -> 64 | H34: Mahindra & Mahindra Financial Services | I34: NSE | J34: -955.8 | K34: 27 | L34: 38 | M34: =SUM(K34,L34) -> 65
A35: Sundaram Finance | B35: NSE | C35: -1142.35 | D35: 28 | E35: 38 | F35: =SUM(D35,E35) -> 66 | H35: Sundaram Finance | I35: NSE | J35: 3041.3 | K35: 35 | L35: 28 | M35: =SUM(K35,L35) -> 63
A36: L&T Finance | B36: NSE | C36: 548.48 | D36: 30 | E36: 42 | F36: =SUM(D36,E36) -> 72 | H36: L&T Finance | I36: NSE | J36: -493.65 | K36: 33 | L36: 37 | M36: =SUM(K36,L36) -> 70
A37: Aditya Birla Capital | B37: NSE | C37: -2292.15 | D37: 27 | E37: 45 | F37: =SUM(D37,E37) -> 72 | H37: Aditya Birla Capital | I37: NSE | J37: 2280.9 | K37: 35 | L37: 32 | M37: =SUM(K37,L37) -> 67
A38: Muthoot Finance | B38: NSE | C38: 1166.85 | D38: 38 | E38: 33 | F38: =SUM(D38,E38) -> 71 | H38: Muthoot Finance | I38: NSE | J38: 882.35 | K38: 34 | L38: 32 | M38: =SUM(K38,L38) -> 66
... A41: Bajaj Finance | B41: NSE | C41: -50.5 | D41: 33 | E41: 33 | F41: =SUM(D41,E41) -> 66 | H41: Bajaj Finance | I41: NSE | J41: -1214.7 | K41: 28 | L41: 38 | M41: =SUM(K41,L41) -> 66
A42: TOTAL | C42: =SUM(C27:C41) -> -7706.82 | D42: =SUM(D27:D41) -> 445 | E42: =SUM(E27:E41) -> 593 | F42: =SUM(F27:F41) -> 1038 | H42: TOTAL | J42: =SUM(J27:J41) -> 18164.3 | K42: =SUM(K27:K41) -> 486 | L42: =SUM(L27:L41) -> 497 | M42: =SUM(M27:M41) -> 983
A44: Q3 (Quarter 3): October 2, 2025 – December 31, 2025
A45: BUY / LONG CALL SIDE | H45: SELL / SHORT CALL SIDE
A46: Company Name | B46: Segment | C46: P&L (₹) | D46: Wins | E46: Losses | F46: Total Trades | H46: Company Name | I46: Segment | J46: P&L (₹) | K46: Wins | L46: Losses | M46: Total Trades
A47: Aavas Financiers | B47: NSE | C47: -248.1 | D47: 27 | E47: 37 | F47: =SUM(D47,E47) -> 64 | H47: Aavas Financiers | I47: NSE | J47: 610.35 | K47: 28 | L47: 35 | M47: =SUM(K47,L47) -> 63
...

Sheet PPS
A1: NBFC – General Sector | Backtesting Report
A2: Student: Vishv Jeet Singh Thakur | Institution: UPES | Strategy: Pivort Point Strandard (PPS) Intraday (5-Minute) | Time: 9:15 AM – 3:00 PM | FY 2025–26
A4: Q1 (Quarter 1): April 1, 2025 – June 30, 2025
A5: BUY / LONG CALL SIDE | H5: SELL / SHORT CALL SIDE
A6: Company Name | B6: Segment | C6: P&L (₹) | D6: Wins | E6: Losses | F6: Total Trades | H6: Company Name | I6: Segment | J6: P&L (₹) | K6: Wins | L6: Losses | M6: Total Trades
A7: Aavas Financiers | B7: NSE | C7: 1228.7 | D7: 9 | E7: 11 | F7: =SUM(D7,E7) -> 20 | H7: Aavas Financiers | I7: NSE | J7: -722.1 | K7: 8 | L7: 18 | M7: =SUM(K7,L7) -> 26
