Workbook

Sheet Cover Page
A1: PORTFOLIO BASKET TRACKERS — WEEKLY PERFORMANCE REPORT
A2: 7-Basket Buy-and-Hold Tracking | 6/30/2026 - 7/31/2026 (5 Weekly Checkpoints)
A4: Prepared By | B4: Vishv Jeet Singh Thakur
A5: Submitted To | B5: Nikesh Ruparel
A6: Institution | B6: UPES
A7: Programme | B7: MBA in Strategic Financial Management in collaboration with EY
A8: Batch | B8: F4- Jun-2026
A9: Report Type | B9: Weekly Portfolio Basket Performance Tracker
A10: Investment Universe | B10: NSE-Listed Equities - 7 Baskets, Equal-Weighted at Inception
A12: BASKET SUMMARY - LATEST (WEEK 5) HOLDINGS & RETURN
A13: # | B13: Basket | C13: Holdings | D13: Total Investment (Rs) | E13: Return (Week 5)
A14: 1 | B14: Method 1 | C14: ='Method 1'!A87 -> 11 | D14: ='Method 1'!B87 -> 114341.55 | E14: ='Method 1'!F87 -> -0.026531038
A15: 2 | B15: Method 2 | C15: ='Method 2'!A91 -> 12 | D15: ='Method 2'!B91 -> 56331.88 | E15: ='Method 2'!F91 -> 0.075766333
A16: 3 | B16: Method 3 | C16: ='Method 3'!A87 -> 11 | D16: ='Method 3'!B87 -> 22506.79 | E16: ='Method 3'!F87 -> 0.018406445
A17: 4 | B17: Method 4 | C17: ='Method 4'!A79 -> 9 | D17: ='Method 4'!B79 -> 1153084 | E17: ='Method 4'!F79 -> 0.011477655
A18: 5 | B18: Method 5 | C18: ='Method 5'!A99 -> 14 | D18: ='Method 5'!B99 -> 134726.25 | E18: ='Method 5'!F99 -> 0.007353875
A19: 6 | B19: Method 6 | C19: ='Method 6'!A103 -> 15 | D19: ='Method 6'!B103 -> 40620.12 | E19: ='Method 6'!F103 -> 0.038195111
A20: 7 | B20: Method Self | C20: ='Method Self'!A119 -> 19 | D20: ='Method Self'!B119 -> 203585.65 | E20: ='Method Self'!F119 -> 0.04375996
A21: TOTAL / AVERAGE ACROSS ALL BASKETS | C21: =SUM(C14:C20) -> 91 | D21: =SUM(D14:D20) -> 1725196.2 | E21: =AVERAGE(E14:E20) -> 0.024061192
A23: Note: Holdings, Total Investment and Return figures pull live from the Week 5 snapshot on each basket sheet.

Sheet Content
A1: TABLE OF CONTENTS
A2: Portfolio Basket Trackers - Weekly Performance Report | 7 Baskets | 5 Weekly Checkpoints
A4: # | B4: Section | C4: What's Inside | D4: Go To
A5: 1 | B5: Cover Page | C5: Report details, submission info & basket-level Week 5 holdings / return summary | D5: Open sheet
A6: 2 | B6: Method 1 | C6: Method 1 - 5-week basket tracking: holdings, weighted allocation & weekly return snapshots | D6: Open sheet
A7: 3 | B7: Method 2 | C7: Method 2 - 5-week basket tracking: holdings, weighted allocation & weekly return snapshots | D7: Open sheet
A8: 4 | B8: Method 3 | C8: Method 3 - 5-week basket tracking: holdings, weighted allocation & weekly return snapshots | D8: Open sheet
A9: 5 | B9: Method 4 | C9: Method 4 - 5-week basket tracking: holdings, weighted allocation & weekly return snapshots | D9: Open sheet
A10: 6 | B10: Method 5 | C10: Method 5 - 5-week basket tracking: holdings, weighted allocation & weekly return snapshots | D10: Open sheet
A11: 7 | B11: Method 6 | C11: Method 6 - 5-week basket tracking: holdings, weighted allocation & weekly return snapshots | D11: Open sheet
A12: 8 | B12: Method Self | C12: Method Self - 5-week basket tracking: holdings, weighted allocation & weekly return snapshots | D12: Open sheet
A13: Note: Click "Open sheet" to jump directly to a section. Each basket sheet shows 5 weekly snapshots (holdings, capital deployed, growth, return) followed by the full stock-level holdings table for that week.

Sheet Method 1
A1: PORTFOLIO BASKET TRACKER — METHOD 1
A2: Student: Vishv Jeet Singh Thakur | Institution: UPES | Weekly Basket Performance Tracking (Basis Fixed at Inception)
A4: WEEK 1 SNAPSHOT — 6/30/2026 - 7/3/2026 | I4: QUERY / SCREENING CRITERIA
A5: Reference stock (basis fixed at inception): Polycab India Ltd (₹9961) | I5: Return on equity > 15 AND
A6: Holdings | B6: Total Investment (₹) | D6: Growth (₹) | F6: Return (6/30/2026 - 7/3/2026) | I6: Sales growth > 15 AND
A7: =COUNT(B11:B21) -> 11 | B7: =F22 -> 114341.55 | D7: =G22 -> 113377.1 | F7: =(G22-F22)/F22 -> -0.0084348166 | I7: Change in FII holding > 1
A9: HOLDINGS — WEEK 1
A10: Company Name | B10: Day 1 Closing (₹) | C10: 1 Week Closing (₹) | D10: Return (%) | E10: Basis (Shares) | F10: Investment (₹) | G10: Growth (₹)
A11: Vedanta Ltd | B11: 280.75 | C11: 280.4 | D11: =(C11-B11)/B11 -> -0.0012466607 | E11: =ROUND($B$21/B11,0) -> 35 | F11: =B11*E11 -> 9826.25 | G11: =C11*E11 -> 9814
A12: Premier Energies Ltd | B12: 1051 | C12: 1046.8 | D12: =(C12-B12)/B12 -> -0.0039961941 | E12: =ROUND($B$21/B12,0) -> 9 | F12: =B12*E12 -> 9459 | G12: =C12*E12 -> 9421.2
A13: Aegis Logistics Ltd | B13: 1173.95 | C13: 1325.4 | D13: =(C13-B13)/B13 -> 0.1290089 | E13: =ROUND($B$21/B13,0) -> 8 | F13: =B13*E13 -> 9391.6 | G13: =C13*E13 -> 10603.2
A14: Glenmark Pharmaceuticals Ltd | B14: 2204.3 | C14: 2211 | D14: =(C14-B14)/B14 -> 0.0030395137 | E14: =ROUND($B$21/B14,0) -> 5 | F14: =B14*E14 -> 11021.5 | G14: =C14*E14 -> 11055
A15: Multi Commodity Exchange of India Ltd | B15: 2837.2 | C15: 2814 | D15: =(C15-B15)/B15 -> -0.008177076 | E15: =ROUND($B$21/B15,0) -> 4 | F15: =B15*E15 -> 11348.8 | G15: =C15*E15 -> 11256
A16: Aditya Infotech Ltd | B16: 3647 | C16: 3588.4 | D16: =(C16-B16)/B16 -> -0.016068001 | E16: =ROUND($B$21/B16,0) -> 3 | F16: =B16*E16 -> 10941 | G16: =C16*E16 -> 10765.2
A17: BSE Ltd | B17: 3865.6 | C17: 3816.6 | D17: =(C17-B17)/B17 -> -0.012675911 | E17: =ROUND($B$21/B17,0) -> 3 | F17: =B17*E17 -> 11596.8 | G17: =C17*E17 -> 11449.8
A18: Hero MotoCorp Ltd | B18: 4794.3 | C18: 4852.6 | D18: =(C18-B18)/B18 -> 0.012160274 | E18: =ROUND($B$21/B18,0) -> 2 | F18: =B18*E18 -> 9588.6 | G18: =C18*E18 -> 9705.2
A19: GE Vernova T&D India Ltd | B19: 4944 | C19: 4401.5 | D19: =(C19-B19)/B19 -> -0.10972896 | E19: =ROUND($B$21/B19,0) -> 2 | F19: =B19*E19 -> 9888 | G19: =C19*E19 -> 8803
A20: Cummins India Ltd | B20: 5659.5 | C20: 5478 | D20: =(C20-B20)/B20 -> -0.032069971 | E20: =ROUND($B$21/B20,0) -> 2 | F20: =B20*E20 -> 11319 | G20: =C20*E20 -> 10956
A21: Polycab India Ltd | B21: 9961 | C21: 9548.5 | D21: =(C21-B21)/B21 -> -0.041411505 | E21: =ROUND($B$21/B21,0) -> 1 | F21: =B21*E21 -> 9961 | G21: =C21*E21 -> 9548.5
A22: Portfolio Total | F22: =SUM(F11:F21) -> 114341.55 | G22: =SUM(G11:G21) -> 113377.1
A24: WEEK 2 SNAPSHOT — 6/30/2026 - 7/10/2026
A25: Reference stock (basis fixed at inception): Hero MotoCorp Ltd (₹4794.3)
A26: Holdings | B26: Total Investment (₹) | D26: Growth (₹) | F26: Return (6/30/2026 - 7/10/2026)
A27: =COUNT(B31:B41) -> 11 | B27: =F42 -> 114341.55 | D27: =G42 -> 114188.05 | F27: =(G42-F42)/F42 -> -0.0013424691
A29: HOLDINGS — WEEK 2
A30: Company Name | B30: Day 1 Closing (₹) | C30: 2 Week Closing (₹) | D30: Return (%) | E30: Basis (Shares) | F30: Investment (₹) | G30: Growth (₹)
A31: Vedanta Ltd | B31: 280.75 | C31: 272.55 | D31: =(C31-B31)/B31 -> -0.02920748 | E31: =ROUND($B$21/B31,0) -> 35 | F31: =B31*E31 -> 9826.25 | G31: =C31*E31 -> 9539.25
A32: Premier Energies Ltd | B32: 1051 | C32: 1117.2 | D32: =(C32-B32)/B32 -> 0.062987631 | E32: =ROUND($B$21/B32,0) -> 9 | F32: =B32*E32 -> 9459 | G32: =C32*E32 -> 10054.8
A33: Aegis Logistics Ltd | B33: 1173.95 | C33: 1246.1 | D33: =(C33-B33)/B33 -> 0.061459176 | E33: =ROUND($B$21/B33,0) -> 8 | F33: =B33*E33 -> 9391.6 | G33: =C33*E33 -> 9968.8
A34: Glenmark Pharmaceuticals Ltd | B34: 2204.3 | C34: 2282.9 | D34: =(C34-B34)/B34 -> 0.035657578 | E34: =ROUND($B$21/B34,0) -> 5 | F34: =B34*E34 -> 11021.5 | G34: =C34*E34 -> 11414.5
A35: Multi Commodity Exchange of India Ltd | B35: 2837.2 | C35: 2770.7 | D35: =(C35-B35)/B35 -> -0.023438601 | E35: =ROUND($B$21/B35,0) -> 4 | F35: =B35*E35 -> 11348.8 | G35: =C35*E35 -> 11082.8
A36: Aditya Infotech Ltd | B36: 3647 | C36: 3662.4 | D36: =(C36-B36)/B36 -> 0.0042226488 | E36: =ROUND($B$21/B36,0) -> 3 | F36: =B36*E36 -> 10941 | G36: =C36*E36 -> 10987.2
A37: BSE Ltd | B37: 3865.6 | C37: 3811.6 | D37: =(C37-B37)/B37 -> -0.013969371 | E37: =ROUND($B$21/B37,0) -> 3 | F37: =B37*E37 -> 11596.8 | G37: =C37*E37 -> 11434.8
A38: Hero MotoCorp Ltd | B38: 4794.3 | C38: 4949.1 | D38: =(C38-B38)/B38 -> 0.032288342 | E38: =ROUND($B$21/B38,0) -> 2 | F38: =B38*E38 -> 9588.6 | G38: =C38*E38 -> 9898.2
A39: GE Vernova T&D India Ltd | B39: 4944 | C39: 4677.1 | D39: =(C39-B39)/B39 -> -0.053984628 | E39: =ROUND($B$21/B39,0) -> 2 | F39: =B39*E39 -> 9888 | G39: =C39*E39 -> 9354.2
A40: Cummins India Ltd | B40: 5659.5 | C40: 5621.5 | D40: =(C40-B40)/B40 -> -0.0067143741 | E40: =ROUND($B$21/B40,0) -> 2 | F40: =B40*E40 -> 11319 | G40: =C40*E40 -> 11243
A41: Polycab India Ltd | B41: 9961 | C41: 9210.5 | D41: =(C41-B41)/B41 -> -0.075343841 | E41: =ROUND($B$21/B41,0) -> 1 | F41: =B41*E41 -> 9961 | G41: =C41*E41 -> 9210.5
A42: Portfolio Total | F42: =SUM(F31:F41) -> 114341.55 | G42: =SUM(G31:G41) -> 114188.05
A44: WEEK 3 SNAPSHOT — 6/30/2026 - 7/17/2026
A45: Reference stock (basis fixed at inception): Hero MotoCorp Ltd (₹4794.3)
...

Sheet Method 2
A1: PORTFOLIO BASKET TRACKER — METHOD 2
A2: Student: Vishv Jeet Singh Thakur | Institution: UPES | Weekly Basket Performance Tracking (Basis Fixed at Inception)
A4: WEEK 1 SNAPSHOT — 6/30/2026 - 7/3/2026 | I4: QUERY / SCREENING CRITERIA
A5: Reference stock (basis fixed at inception): Hero MotoCorp Ltd (₹4794.3) | I5: Sales > 250 AND
A6: Holdings | B6: Total Investment (₹) | D6: Growth (₹) | F6: Return (6/30/2026 - 7/3/2026) | I6: Debt to equity < 0.3 AND
A7: =COUNT(B11:B22) -> 12 | B7: =F23 -> 56331.88 | D7: =G23 -> 57544.24 | F7: =(G23-F23)/F23 -> 0.021521739 | I7: Interest Coverage Ratio > 4 AND
I8: Return on equity > 15 AND
A9: HOLDINGS — WEEK 1 | I9: Price to Earning < Industry PE AND
A10: Company Name | B10: Day 1 Closing (₹) | C10: 1 Week Closing (₹) | D10: Return (%) | E10: Basis (Shares) | F10: Investment (₹) | G10: Growth (₹) | I10: Dividend yield > 1 AND
A11: NMDC Ltd | B11: 85.16 | C11: 85.4 | D11: =(C11-B11)/B11 -> 0.0028182245 | E11: =ROUND($B$22/B11,0) -> 56 | F11: =B11*E11 -> 4768.96 | G11: =C11*E11 -> 4782.4 | I11: Price to Earning < 20
A12: Wipro Ltd | B12: 170.39 | C12: 176.08 | D12: =(C12-B12)/B12 -> 0.033393979 | E12: =ROUND($B$22/B12,0) -> 28 | F12: =B12*E12 -> 4770.92 | G12: =C12*E12 -> 4930.24
A13: Petronet LNG Ltd | B13: 280.8 | C13: 275.95 | D13: =(C13-B13)/B13 -> -0.01727208 | E13: =ROUND($B$22/B13,0) -> 17 | F13: =B13*E13 -> 4773.6 | G13: =C13*E13 -> 4691.15
A14: ITC Ltd | B14: 286.95 | C14: 289.95 | D14: =(C14-B14)/B14 -> 0.010454783 | E14: =ROUND($B$22/B14,0) -> 17 | F14: =B14*E14 -> 4878.15 | G14: =C14*E14 -> 4929.15
A15: National Aluminium Co Ltd | B15: 339.6 | C15: 347.6 | D15: =(C15-B15)/B15 -> 0.023557126 | E15: =ROUND($B$22/B15,0) -> 14 | F15: =B15*E15 -> 4754.4 | G15: =C15*E15 -> 4866.4
A16: Coal India Ltd | B16: 439.05 | C16: 438.7 | D16: =(C16-B16)/B16 -> -0.00079717572 | E16: =ROUND($B$22/B16,0) -> 11 | F16: =B16*E16 -> 4829.55 | G16: =C16*E16 -> 4825.7
A17: Infosys Ltd | B17: 1000.4 | C17: 1047.2 | D17: =(C17-B17)/B17 -> 0.046781287 | E17: =ROUND($B$22/B17,0) -> 5 | F17: =B17*E17 -> 5002 | G17: =C17*E17 -> 5236
A18: HCL Technologies Ltd | B18: 1071.8 | C18: 1139 | D18: =(C18-B18)/B18 -> 0.062698265 | E18: =ROUND($B$22/B18,0) -> 4 | F18: =B18*E18 -> 4287.2 | G18: =C18*E18 -> 4556
A19: Tata Consultancy Services Ltd | B19: 2031.5 | C19: 2093.5 | D19: =(C19-B19)/B19 -> 0.030519321 | E19: =ROUND($B$22/B19,0) -> 2 | F19: =B19*E19 -> 4063 | G19: =C19*E19 -> 4187
A20: Escorts Kubota Ltd | B20: 2935.9 | C20: 2964.9 | D20: =(C20-B20)/B20 -> 0.0098777206 | E20: =ROUND($B$22/B20,0) -> 2 | F20: =B20*E20 -> 5871.8 | G20: =C20*E20 -> 5929.8
A21: LTM Ltd | B21: 3538 | C21: 3757.8 | D21: =(C21-B21)/B21 -> 0.062125495 | E21: =ROUND($B$22/B21,0) -> 1 | F21: =B21*E21 -> 3538 | G21: =C21*E21 -> 3757.8
A22: Hero MotoCorp Ltd | B22: 4794.3 | C22: 4852.6 | D22: =(C22-B22)/B22 -> 0.012160274 | E22: =ROUND($B$22/B22,0) -> 1 | F22: =B22*E22 -> 4794.3 | G22: =C22*E22 -> 4852.6
A23: Portfolio Total | F23: =SUM(F11:F22) -> 56331.88 | G23: =SUM(G11:G22) -> 57544.24
A25: WEEK 2 SNAPSHOT — 6/30/2026 - 7/10/2026
A26: Reference stock (basis fixed at inception): Hero MotoCorp Ltd (₹4794.3)
A27: Holdings | B27: Total Investment (₹) | D27: Growth (₹) | F27: Return (6/30/2026 - 7/10/2026)
A28: =COUNT(B32:B43) -> 12 | B28: =F44 -> 56331.88 | D28: =G44 -> 58119.8 | F28: =(G44-F44)/F44 -> 0.031739044
A30: HOLDINGS — WEEK 2
A31: Company Name | B31: Day 1 Closing (₹) | C31: 2 Week Closing (₹) | D31: Return (%) | E31: Basis (Shares) | F31: Investment (₹) | G31: Growth (₹)
A32: NMDC Ltd | B32: 85.16 | C32: 84.92 | D32: =(C32-B32)/B32 -> -0.0028182245 | E32: =ROUND($B$22/B32,0) -> 56 | F32: =B32*E32 -> 4768.96 | G32: =C32*E32 -> 4755.52
A33: Wipro Ltd | B33: 170.39 | C33: 175.46 | D33: =(C33-B33)/B33 -> 0.029755267 | E33: =ROUND($B$22/B33,0) -> 28 | F33: =B33*E33 -> 4770.92 | G33: =C33*E33 -> 4912.88
A34: Petronet LNG Ltd | B34: 280.8 | C34: 278.95 | D34: =(C34-B34)/B34 -> -0.0065883191 | E34: =ROUND($B$22/B34,0) -> 17 | F34: =B34*E34 -> 4773.6 | G34: =C34*E34 -> 4742.15
A35: ITC Ltd | B35: 286.95 | C35: 281.75 | D35: =(C35-B35)/B35 -> -0.018121624 | E35: =ROUND($B$22/B35,0) -> 17 | F35: =B35*E35 -> 4878.15 | G35: =C35*E35 -> 4789.75
A36: National Aluminium Co Ltd | B36: 339.6 | C36: 354.85 | D36: =(C36-B36)/B36 -> 0.044905771 | E36: =ROUND($B$22/B36,0) -> 14 | F36: =B36*E36 -> 4754.4 | G36: =C36*E36 -> 4967.9
A37: Coal India Ltd | B37: 439.05 | C37: 429.3 | D37: =(C37-B37)/B37 -> -0.022207038 | E37: =ROUND($B$22/B37,0) -> 11 | F37: =B37*E37 -> 4829.55 | G37: =C37*E37 -> 4722.3
A38: Infosys Ltd | B38: 1000.4 | C38: 1068 | D38: =(C38-B38)/B38 -> 0.067572971 | E38: =ROUND($B$22/B38,0) -> 5 | F38: =B38*E38 -> 5002 | G38: =C38*E38 -> 5340
A39: HCL Technologies Ltd | B39: 1071.8 | C39: 1164.1 | D39: =(C39-B39)/B39 -> 0.086116813 | E39: =ROUND($B$22/B39,0) -> 4 | F39: =B39*E39 -> 4287.2 | G39: =C39*E39 -> 4656.4
A40: Tata Consultancy Services Ltd | B40: 2031.5 | C40: 2181.5 | D40: =(C40-B40)/B40 -> 0.073837066 | E40: =ROUND($B$22/B40,0) -> 2 | F40: =B40*E40 -> 4063 | G40: =C40*E40 -> 4363
A41: Escorts Kubota Ltd | B41: 2935.9 | C41: 2941.8 | D41: =(C41-B41)/B41 -> 0.0020096052 | E41: =ROUND($B$22/B41,0) -> 2 | F41: =B41*E41 -> 5871.8 | G41: =C41*E41 -> 5883.6
A42: LTM Ltd | B42: 3538 | C42: 4037.2 | D42: =(C42-B42)/B42 -> 0.14109666 | E42: =ROUND($B$22/B42,0) -> 1 | F42: =B42*E42 -> 3538 | G42: =C42*E42 -> 4037.2
A43: Hero MotoCorp Ltd | B43: 4794.3 | C43: 4949.1 | D43: =(C43-B43)/B43 -> 0.032288342 | E43: =ROUND($B$22/B43,0) -> 1 | F43: =B43*E43 -> 4794.3 | G43: =C43*E43 -> 4949.1
...

Sheet Method 3
A1: PORTFOLIO BASKET TRACKER — METHOD 3
A2: Student: Vishv Jeet Singh Thakur | Institution: UPES | Weekly Basket Performance Tracking (Basis Fixed at Inception)
A4: WEEK 1 SNAPSHOT — 6/30/2026 - 7/3/2026 | I4: QUERY / SCREENING CRITERIA
A5: Reference stock (basis fixed at inception): Tata Consultancy Services Ltd (₹2031.5) | I5: Price to Earning < 15 AND
A6: Holdings | B6: Total Investment (₹) | D6: Growth (₹) | F6: Return (6/30/2026 - 7/3/2026) | I6: Price to Earning > 0 AND
A7: =COUNT(B11:B21) -> 11 | B7: =F22 -> 22506.79 | D7: =G22 -> 22670.4 | F7: =(G22-F22)/F22 -> 0.0072693618 | I7: ROCE 3yr avg >= 15 AND
I8: Net profit >= 20 AND
A9: HOLDINGS — WEEK 1 | I9: YOY Quarterly profit growth > 0
A10: Company Name | B10: Day 1 Closing (₹) | C10: 1 Week Closing (₹) | D10: Return (%) | E10: Basis (Shares) | F10: Investment (₹) | G10: Growth (₹)
A11: NMDC Ltd | B11: 85.16 | C11: 85.4 | D11: =(C11-B11)/B11 -> 0.0028182245 | E11: =ROUND($B$21/B11,0) -> 24 | F11: =B11*E11 -> 2043.84 | G11: =C11*E11 -> 2049.6
A12: Indian Oil Corporation Ltd | B12: 139.38 | C12: 141.56 | D12: =(C12-B12)/B12 -> 0.015640695 | E12: =ROUND($B$21/B12,0) -> 15 | F12: =B12*E12 -> 2090.7 | G12: =C12*E12 -> 2123.4
A13: Vedanta Ltd | B13: 280.75 | C13: 280.4 | D13: =(C13-B13)/B13 -> -0.0012466607 | E13: =ROUND($B$21/B13,0) -> 7 | F13: =B13*E13 -> 1965.25 | G13: =C13*E13 -> 1962.8
A14: Petronet LNG Ltd | B14: 280.8 | C14: 275.95 | D14: =(C14-B14)/B14 -> -0.01727208 | E14: =ROUND($B$21/B14,0) -> 7 | F14: =B14*E14 -> 1965.6 | G14: =C14*E14 -> 1931.65
A15: Bharat Petroleum Corporation Ltd | B15: 303.55 | C15: 308.15 | D15: =(C15-B15)/B15 -> 0.015154011 | E15: =ROUND($B$21/B15,0) -> 7 | F15: =B15*E15 -> 2124.85 | G15: =C15*E15 -> 2157.05
A16: Indus Towers Ltd | B16: 391.7 | C16: 383.3 | D16: =(C16-B16)/B16 -> -0.021444983 | E16: =ROUND($B$21/B16,0) -> 5 | F16: =B16*E16 -> 1958.5 | G16: =C16*E16 -> 1916.5
A17: Hindustan Petroleum Corp Ltd | B17: 394.45 | C17: 399.25 | D17: =(C17-B17)/B17 -> 0.012168843 | E17: =ROUND($B$21/B17,0) -> 5 | F17: =B17*E17 -> 1972.25 | G17: =C17*E17 -> 1996.25
A18: Life Insurance Corporation Of India | B18: 431.65 | C18: 430.35 | D18: =(C18-B18)/B18 -> -0.0030116993 | E18: =ROUND($B$21/B18,0) -> 5 | F18: =B18*E18 -> 2158.25 | G18: =C18*E18 -> 2151.75
A19: Coal India Ltd | B19: 439.05 | C19: 438.7 | D19: =(C19-B19)/B19 -> -0.00079717572 | E19: =ROUND($B$21/B19,0) -> 5 | F19: =B19*E19 -> 2195.25 | G19: =C19*E19 -> 2193.5
A20: Infosys Ltd | B20: 1000.4 | C20: 1047.2 | D20: =(C20-B20)/B20 -> 0.046781287 | E20: =ROUND($B$21/B20,0) -> 2 | F20: =B20*E20 -> 2000.8 | G20: =C20*E20 -> 2094.4
A21: Tata Consultancy Services Ltd | B21: 2031.5 | C21: 2093.5 | D21: =(C21-B21)/B21 -> 0.030519321 | E21: =ROUND($B$21/B21,0) -> 1 | F21: =B21*E21 -> 2031.5 | G21: =C21*E21 -> 2093.5
A22: Portfolio Total | F22: =SUM(F11:F21) -> 22506.79 | G22: =SUM(G11:G21) -> 22670.4
A24: WEEK 2 SNAPSHOT — 6/30/2026 - 7/10/2026
A25: Reference stock (basis fixed at inception): Hero MotoCorp Ltd (₹4794.3)
A26: Holdings | B26: Total Investment (₹) | D26: Growth (₹) | F26: Return (6/30/2026 - 7/10/2026)
A27: =COUNT(B31:B41) -> 11 | B27: =F42 -> 22506.79 | D27: =G42 -> 22837.73 | F27: =(G42-F42)/F42 -> 0.014704007
A29: HOLDINGS — WEEK 2
A30: Company Name | B30: Day 1 Closing (₹) | C30: 2 Week Closing (₹) | D30: Return (%) | E30: Basis (Shares) | F30: Investment (₹) | G30: Growth (₹)
A31: NMDC Ltd | B31: 85.16 | C31: 84.92 | D31: =(C31-B31)/B31 -> -0.0028182245 | E31: =ROUND($B$21/B31,0) -> 24 | F31: =B31*E31 -> 2043.84 | G31: =C31*E31 -> 2038.08
A32: Indian Oil Corporation Ltd | B32: 139.38 | C32: 138.96 | D32: =(C32-B32)/B32 -> -0.0030133448 | E32: =ROUND($B$21/B32,0) -> 15 | F32: =B32*E32 -> 2090.7 | G32: =C32*E32 -> 2084.4
A33: Vedanta Ltd | B33: 280.75 | C33: 272.55 | D33: =(C33-B33)/B33 -> -0.02920748 | E33: =ROUND($B$21/B33,0) -> 7 | F33: =B33*E33 -> 1965.25 | G33: =C33*E33 -> 1907.85
A34: Petronet LNG Ltd | B34: 280.8 | C34: 278.95 | D34: =(C34-B34)/B34 -> -0.0065883191 | E34: =ROUND($B$21/B34,0) -> 7 | F34: =B34*E34 -> 1965.6 | G34: =C34*E34 -> 1952.65
A35: Bharat Petroleum Corporation Ltd | B35: 303.55 | C35: 309.75 | D35: =(C35-B35)/B35 -> 0.020424971 | E35: =ROUND($B$21/B35,0) -> 7 | F35: =B35*E35 -> 2124.85 | G35: =C35*E35 -> 2168.25
A36: Indus Towers Ltd | B36: 391.7 | C36: 406.15 | D36: =(C36-B36)/B36 -> 0.036890477 | E36: =ROUND($B$21/B36,0) -> 5 | F36: =B36*E36 -> 1958.5 | G36: =C36*E36 -> 2030.75
A37: Hindustan Petroleum Corp Ltd | B37: 394.45 | C37: 395.3 | D37: =(C37-B37)/B37 -> 0.0021548992 | E37: =ROUND($B$21/B37,0) -> 5 | F37: =B37*E37 -> 1972.25 | G37: =C37*E37 -> 1976.5
A38: Life Insurance Corporation Of India | B38: 431.65 | C38: 443.05 | D38: =(C38-B38)/B38 -> 0.026410286 | E38: =ROUND($B$21/B38,0) -> 5 | F38: =B38*E38 -> 2158.25 | G38: =C38*E38 -> 2215.25
A39: Coal India Ltd | B39: 439.05 | C39: 429.3 | D39: =(C39-B39)/B39 -> -0.022207038 | E39: =ROUND($B$21/B39,0) -> 5 | F39: =B39*E39 -> 2195.25 | G39: =C39*E39 -> 2146.5
A40: Infosys Ltd | B40: 1000.4 | C40: 1068 | D40: =(C40-B40)/B40 -> 0.067572971 | E40: =ROUND($B$21/B40,0) -> 2 | F40: =B40*E40 -> 2000.8 | G40: =C40*E40 -> 2136
A41: Tata Consultancy Services Ltd | B41: 2031.5 | C41: 2181.5 | D41: =(C41-B41)/B41 -> 0.073837066 | E41: =ROUND($B$21/B41,0) -> 1 | F41: =B41*E41 -> 2031.5 | G41: =C41*E41 -> 2181.5
A42: Portfolio Total | F42: =SUM(F31:F41) -> 22506.79 | G42: =SUM(G31:G41) -> 22837.73
A44: WEEK 3 SNAPSHOT — 6/30/2026 - 7/17/2026
...

Sheet Method 4
A1: PORTFOLIO BASKET TRACKER — METHOD 4
A2: Student: Vishv Jeet Singh Thakur | Institution: UPES | Weekly Basket Performance Tracking (Basis Fixed at Inception)
A4: WEEK 1 SNAPSHOT — 6/30/2026 - 7/3/2026 | I4: QUERY / SCREENING CRITERIA
A5: Reference stock (basis fixed at inception): MRF Ltd (₹127820) | I5: Method:- Peter Lynch
A6: Holdings | B6: Total Investment (₹) | D6: Growth (₹) | F6: Return (6/30/2026 - 7/3/2026) | I6: PEG Ratio < 1 AND
A7: =COUNT(B11:B19) -> 9 | B7: =F20 -> 1153084 | D7: =G20 -> 1169232.5 | F7: =(G20-F20)/F20 -> 0.014004617 | I7: Sales > 500 AND
I8: Price to Earning < 40 AND
A9: HOLDINGS — WEEK 1 | I9: Profit growth > 20 AND
A10: Company Name | B10: Day 1 Closing (₹) | C10: 1 Week Closing (₹) | D10: Return (%) | E10: Basis (Shares) | F10: Investment (₹) | G10: Growth (₹) | I10: Debt to equity < 0.2 AND
A11: Suzlon Energy Ltd | B11: 58.9 | C11: 56.87 | D11: =(C11-B11)/B11 -> -0.034465195 | E11: =ROUND($B$19/B11,0) -> 2170 | F11: =B11*E11 -> 127813 | G11: =C11*E11 -> 123407.9 | I11: Price to Cash Flow > 5
A12: General Insurance Corporation of India | B12: 363.5 | C12: 360.95 | D12: =(C12-B12)/B12 -> -0.0070151307 | E12: =ROUND($B$19/B12,0) -> 352 | F12: =B12*E12 -> 127952 | G12: =C12*E12 -> 127054.4
A13: IPCA Laboratories Ltd | B13: 1701 | C13: 1778.9 | D13: =(C13-B13)/B13 -> 0.04579659 | E13: =ROUND($B$19/B13,0) -> 75 | F13: =B13*E13 -> 127575 | G13: =C13*E13 -> 133417.5
A14: Godfrey Phillips India Ltd | B14: 2173.1 | C14: 2170.1 | D14: =(C14-B14)/B14 -> -0.0013805163 | E14: =ROUND($B$19/B14,0) -> 59 | F14: =B14*E14 -> 128212.9 | G14: =C14*E14 -> 128035.9
A15: Glenmark Pharmaceuticals Ltd | B15: 2204.3 | C15: 2211 | D15: =(C15-B15)/B15 -> 0.0030395137 | E15: =ROUND($B$19/B15,0) -> 58 | F15: =B15*E15 -> 127849.4 | G15: =C15*E15 -> 128238
A16: Escorts Kubota Ltd | B16: 2935.9 | C16: 2964.9 | D16: =(C16-B16)/B16 -> 0.0098777206 | E16: =ROUND($B$19/B16,0) -> 44 | F16: =B16*E16 -> 129179.6 | G16: =C16*E16 -> 130455.6
A17: Hero MotoCorp Ltd | B17: 4794.3 | C17: 4852.6 | D17: =(C17-B17)/B17 -> 0.012160274 | E17: =ROUND($B$19/B17,0) -> 27 | F17: =B17*E17 -> 129446.1 | G17: =C17*E17 -> 131020.2
A18: Bajaj Holdings and Investment Ltd | B18: 10603 | C18: 11079 | D18: =(C18-B18)/B18 -> 0.044892955 | E18: =ROUND($B$19/B18,0) -> 12 | F18: =B18*E18 -> 127236 | G18: =C18*E18 -> 132948
A19: MRF Ltd | B19: 127820 | C19: 134655 | D19: =(C19-B19)/B19 -> 0.053473635 | E19: =ROUND($B$19/B19,0) -> 1 | F19: =B19*E19 -> 127820 | G19: =C19*E19 -> 134655
A20: Portfolio Total | F20: =SUM(F11:F19) -> 1153084 | G20: =SUM(G11:G19) -> 1169232.5
A22: WEEK 2 SNAPSHOT — 6/30/2026 - 7/10/2026
A23: Reference stock (basis fixed at inception): Hero MotoCorp Ltd (₹4794.3)
A24: Holdings | B24: Total Investment (₹) | D24: Growth (₹) | F24: Return (6/30/2026 - 7/10/2026)
A25: =COUNT(B29:B37) -> 9 | B25: =F38 -> 1153084 | D25: =G38 -> 1162127.7 | F25: =(G38-F38)/F38 -> 0.0078430539
A27: HOLDINGS — WEEK 2
A28: Company Name | B28: Day 1 Closing (₹) | C28: 2 Week Closing (₹) | D28: Return (%) | E28: Basis (Shares) | F28: Investment (₹) | G28: Growth (₹)
A29: Suzlon Energy Ltd | B29: 58.9 | C29: 53.92 | D29: =(C29-B29)/B29 -> -0.084550085 | E29: =ROUND($B$19/B29,0) -> 2170 | F29: =B29*E29 -> 127813 | G29: =C29*E29 -> 117006.4
A30: General Insurance Corporation of India | B30: 363.5 | C30: 365 | D30: =(C30-B30)/B30 -> 0.0041265475 | E30: =ROUND($B$19/B30,0) -> 352 | F30: =B30*E30 -> 127952 | G30: =C30*E30 -> 128480
A31: IPCA Laboratories Ltd | B31: 1701 | C31: 1787.9 | D31: =(C31-B31)/B31 -> 0.051087596 | E31: =ROUND($B$19/B31,0) -> 75 | F31: =B31*E31 -> 127575 | G31: =C31*E31 -> 134092.5
A32: Godfrey Phillips India Ltd | B32: 2173.1 | C32: 2115.3 | D32: =(C32-B32)/B32 -> -0.026597948 | E32: =ROUND($B$19/B32,0) -> 59 | F32: =B32*E32 -> 128212.9 | G32: =C32*E32 -> 124802.7
A33: Glenmark Pharmaceuticals Ltd | B33: 2204.3 | C33: 2282.9 | D33: =(C33-B33)/B33 -> 0.035657578 | E33: =ROUND($B$19/B33,0) -> 58 | F33: =B33*E33 -> 127849.4 | G33: =C33*E33 -> 132408.2
A34: Escorts Kubota Ltd | B34: 2935.9 | C34: 2941.8 | D34: =(C34-B34)/B34 -> 0.0020096052 | E34: =ROUND($B$19/B34,0) -> 44 | F34: =B34*E34 -> 129179.6 | G34: =C34*E34 -> 129439.2
A35: Hero MotoCorp Ltd | B35: 4794.3 | C35: 4949.1 | D35: =(C35-B35)/B35 -> 0.032288342 | E35: =ROUND($B$19/B35,0) -> 27 | F35: =B35*E35 -> 129446.1 | G35: =C35*E35 -> 133625.7
A36: Bajaj Holdings and Investment Ltd | B36: 10603 | C36: 10654 | D36: =(C36-B36)/B36 -> 0.0048099594 | E36: =ROUND($B$19/B36,0) -> 12 | F36: =B36*E36 -> 127236 | G36: =C36*E36 -> 127848
A37: MRF Ltd | B37: 127820 | C37: 134425 | D37: =(C37-B37)/B37 -> 0.051674229 | E37: =ROUND($B$19/B37,0) -> 1 | F37: =B37*E37 -> 127820 | G37: =C37*E37 -> 134425
A38: Portfolio Total | F38: =SUM(F29:F37) -> 1153084 | G38: =SUM(G29:G37) -> 1162127.7
A40: WEEK 3 SNAPSHOT — 6/30/2026 - 7/17/2026
A41: Reference stock (basis fixed at inception): Hero MotoCorp Ltd (₹4794.3)
A42: Holdings | B42: Total Investment (₹) | D42: Growth (₹) | F42: Return (6/30/2026 - 7/17/2026)
A43: =COUNT(B47:B55) -> 9 | B43: =F56 -> 1153084 | D43: =G56 -> 1154196.7 | F43: =(G56-F56)/F56 -> 0.0009649774
A45: HOLDINGS — WEEK 3
...

Sheet Method 5
A1: PORTFOLIO BASKET TRACKER — METHOD 5
A2: Student: Vishv Jeet Singh Thakur | Institution: UPES | Weekly Basket Performance Tracking (Basis Fixed at Inception)
A4: WEEK 1 SNAPSHOT — 6/30/2026 - 7/3/2026 | I4: QUERY / SCREENING CRITERIA
A5: Reference stock (basis fixed at inception): Bajaj Auto Ltd (₹9716) | I5: Method:- Joel Greenblatt
A6: Holdings | B6: Total Investment (₹) | D6: Growth (₹) | F6: Return (6/30/2026 - 7/3/2026) | I6: G Factor >= 7 AND
A7: =COUNT(B11:B24) -> 14 | B7: =F25 -> 134726.25 | D7: =G25 -> 136239.98 | F7: =(G25-F25)/F25 -> 0.011235598 | I7: Market Capitalization > 25000
A9: HOLDINGS — WEEK 1
A10: Company Name | B10: Day 1 Closing (₹) | C10: 1 Week Closing (₹) | D10: Return (%) | E10: Basis (Shares) | F10: Investment (₹) | G10: Growth (₹)
A11: Central Bank of India Ltd | B11: 32.53 | C11: 32.8 | D11: =(C11-B11)/B11 -> 0.0083000307 | E11: =ROUND($B$24/B11,0) -> 299 | F11: =B11*E11 -> 9726.47 | G11: =C11*E11 -> 9807.2
A12: NMDC Ltd | B12: 85.16 | C12: 85.4 | D12: =(C12-B12)/B12 -> 0.0028182245 | E12: =ROUND($B$24/B12,0) -> 114 | F12: =B12*E12 -> 9708.24 | G12: =C12*E12 -> 9735.6
A13: Physicswallah Ltd | B13: 124.13 | C13: 130.16 | D13: =(C13-B13)/B13 -> 0.048578104 | E13: =ROUND($B$24/B13,0) -> 78 | F13: =B13*E13 -> 9682.14 | G13: =C13*E13 -> 10152.48
A14: Indian Oil Corporation Ltd | B14: 139.38 | C14: 141.56 | D14: =(C14-B14)/B14 -> 0.015640695 | E14: =ROUND($B$24/B14,0) -> 70 | F14: =B14*E14 -> 9756.6 | G14: =C14*E14 -> 9909.2
A15: Bank of India Ltd | B15: 140.4 | C15: 144.05 | D15: =(C15-B15)/B15 -> 0.025997151 | E15: =ROUND($B$24/B15,0) -> 69 | F15: =B15*E15 -> 9687.6 | G15: =C15*E15 -> 9939.45
A16: Vedanta Ltd | B16: 280.75 | C16: 280.4 | D16: =(C16-B16)/B16 -> -0.0012466607 | E16: =ROUND($B$24/B16,0) -> 35 | F16: =B16*E16 -> 9826.25 | G16: =C16*E16 -> 9814
A17: Bharat Petroleum Corporation Ltd | B17: 303.55 | C17: 308.15 | D17: =(C17-B17)/B17 -> 0.015154011 | E17: =ROUND($B$24/B17,0) -> 32 | F17: =B17*E17 -> 9713.6 | G17: =C17*E17 -> 9860.8
A18: Life Insurance Corporation Of India | B18: 431.65 | C18: 430.35 | D18: =(C18-B18)/B18 -> -0.0030116993 | E18: =ROUND($B$24/B18,0) -> 23 | F18: =B18*E18 -> 9927.95 | G18: =C18*E18 -> 9898.05
A19: Coal India Ltd | B19: 439.05 | C19: 438.7 | D19: =(C19-B19)/B19 -> -0.00079717572 | E19: =ROUND($B$24/B19,0) -> 22 | F19: =B19*E19 -> 9659.1 | G19: =C19*E19 -> 9651.4
A20: Hindustan Zinc Ltd | B20: 533.15 | C20: 536.55 | D20: =(C20-B20)/B20 -> 0.0063771922 | E20: =ROUND($B$24/B20,0) -> 18 | F20: =B20*E20 -> 9596.7 | G20: =C20*E20 -> 9657.9
A21: Nippon Life India Asset Management Ltd | B21: 1162 | C21: 1218.2 | D21: =(C21-B21)/B21 -> 0.048364888 | E21: =ROUND($B$24/B21,0) -> 8 | F21: =B21*E21 -> 9296 | G21: =C21*E21 -> 9745.6
A22: Waaree Energies Ltd | B22: 2947 | C22: 2859.2 | D22: =(C22-B22)/B22 -> -0.02979301 | E22: =ROUND($B$24/B22,0) -> 3 | F22: =B22*E22 -> 8841 | G22: =C22*E22 -> 8577.6
... A24: Bajaj Auto Ltd | B24: 9716 | C24: 9785.5 | D24: =(C24-B24)/B24 -> 0.0071531494 | E24: =ROUND($B$24/B24,0) -> 1 | F24: =B24*E24 -> 9716 | G24: =C24*E24 -> 9785.5
A25: Portfolio Total | F25: =SUM(F11:F24) -> 134726.25 | G25: =SUM(G11:G24) -> 136239.98
A27: WEEK 2 SNAPSHOT — 6/30/2026 - 7/10/2026
A28: Reference stock (basis fixed at inception): Hero MotoCorp Ltd (₹4794.3)
A29: Holdings | B29: Total Investment (₹) | D29: Growth (₹) | F29: Return (6/30/2026 - 7/10/2026)
A30: =COUNT(B34:B47) -> 14 | B30: =F48 -> 134726.25 | D30: =G48 -> 137928.72 | F30: =(G48-F48)/F48 -> 0.023770201
A32: HOLDINGS — WEEK 2
A33: Company Name | B33: Day 1 Closing (₹) | C33: 2 Week Closing (₹) | D33: Return (%) | E33: Basis (Shares) | F33: Investment (₹) | G33: Growth (₹)
A34: Central Bank of India Ltd | B34: 32.53 | C34: 32.6 | D34: =(C34-B34)/B34 -> 0.0021518598 | E34: =ROUND($B$24/B34,0) -> 299 | F34: =B34*E34 -> 9726.47 | G34: =C34*E34 -> 9747.4
A35: NMDC Ltd | B35: 85.16 | C35: 84.92 | D35: =(C35-B35)/B35 -> -0.0028182245 | E35: =ROUND($B$24/B35,0) -> 114 | F35: =B35*E35 -> 9708.24 | G35: =C35*E35 -> 9680.88
A36: Physicswallah Ltd | B36: 124.13 | C36: 147.43 | D36: =(C36-B36)/B36 -> 0.18770644 | E36: =ROUND($B$24/B36,0) -> 78 | F36: =B36*E36 -> 9682.14 | G36: =C36*E36 -> 11499.54
A37: Indian Oil Corporation Ltd | B37: 139.38 | C37: 138.96 | D37: =(C37-B37)/B37 -> -0.0030133448 | E37: =ROUND($B$24/B37,0) -> 70 | F37: =B37*E37 -> 9756.6 | G37: =C37*E37 -> 9727.2
A38: Bank of India Ltd | B38: 140.4 | C38: 144.9 | D38: =(C38-B38)/B38 -> 0.032051282 | E38: =ROUND($B$24/B38,0) -> 69 | F38: =B38*E38 -> 9687.6 | G38: =C38*E38 -> 9998.1
A39: Vedanta Ltd | B39: 280.75 | C39: 272.55 | D39: =(C39-B39)/B39 -> -0.02920748 | E39: =ROUND($B$24/B39,0) -> 35 | F39: =B39*E39 -> 9826.25 | G39: =C39*E39 -> 9539.25
A40: Bharat Petroleum Corporation Ltd | B40: 303.55 | C40: 309.75 | D40: =(C40-B40)/B40 -> 0.020424971 | E40: =ROUND($B$24/B40,0) -> 32 | F40: =B40*E40 -> 9713.6 | G40: =C40*E40 -> 9912
A41: Life Insurance Corporation Of India | B41: 431.65 | C41: 443.05 | D41: =(C41-B41)/B41 -> 0.026410286 | E41: =ROUND($B$24/B41,0) -> 23 | F41: =B41*E41 -> 9927.95 | G41: =C41*E41 -> 10190.15
A42: Coal India Ltd | B42: 439.05 | C42: 429.3 | D42: =(C42-B42)/B42 -> -0.022207038 | E42: =ROUND($B$24/B42,0) -> 22 | F42: =B42*E42 -> 9659.1 | G42: =C42*E42 -> 9444.6
A43: Hindustan Zinc Ltd | B43: 533.15 | C43: 536.95 | D43: =(C43-B43)/B43 -> 0.0071274501 | E43: =ROUND($B$24/B43,0) -> 18 | F43: =B43*E43 -> 9596.7 | G43: =C43*E43 -> 9665.1
A44: Nippon Life India Asset Management Ltd | B44: 1162 | C44: 1212.7 | D44: =(C44-B44)/B44 -> 0.04363167 | E44: =ROUND($B$24/B44,0) -> 8 | F44: =B44*E44 -> 9296 | G44: =C44*E44 -> 9701.6
A45: Waaree Energies Ltd | B45: 2947 | C45: 2922.9 | D45: =(C45-B45)/B45 -> -0.0081778079 | E45: =ROUND($B$24/B45,0) -> 3 | F45: =B45*E45 -> 8841 | G45: =C45*E45 -> 8768.7
...

Sheet Method 6
A1: PORTFOLIO BASKET TRACKER — METHOD 6
A2: Student: Vishv Jeet Singh Thakur | Institution: UPES | Weekly Basket Performance Tracking (Basis Fixed at Inception)
A4: WEEK 1 SNAPSHOT — 6/30/2026 - 7/3/2026 | I4: QUERY / SCREENING CRITERIA
A5: Reference stock (basis fixed at inception): Technocraft Industries (India) Ltd (₹2564.9) | I5: Method:- Joseph Piotroski
A6: Holdings | B6: Total Investment (₹) | D6: Growth (₹) | F6: Return (6/30/2026 - 7/3/2026) | I6: Piotroski score > 6 AND
A7: =COUNT(B11:B25) -> 15 | B7: =F26 -> 40620.12 | D7: =G26 -> 41305.65 | F7: =(G26-F26)/F26 -> 0.016876612 | I7: Return on capital employed > 15 AND
I8: Return on equity > 15 AND
A9: HOLDINGS — WEEK 1 | I9: YOY Quarterly profit growth > 7 AND
A10: Company Name | B10: Day 1 Closing (₹) | C10: 1 Week Closing (₹) | D10: Return (%) | E10: Basis (Shares) | F10: Investment (₹) | G10: Growth (₹) | I10: Current ratio > 1 AND
A11: Indiabulls Ltd | B11: 27.81 | C11: 29.3 | D11: =(C11-B11)/B11 -> 0.05357785 | E11: =ROUND($B$25/B11,0) -> 92 | F11: =B11*E11 -> 2558.52 | G11: =C11*E11 -> 2695.6 | I11: Price to book value < 3 AND
A12: Jayaswal Neco Industries Ltd | B12: 84.95 | C12: 90.99 | D12: =(C12-B12)/B12 -> 0.071100647 | E12: =ROUND($B$25/B12,0) -> 30 | F12: =B12*E12 -> 2548.5 | G12: =C12*E12 -> 2729.7 | I12: Dividend yield < 4 AND
A13: JK Tyre & Industries Ltd | B13: 394.05 | C13: 412.55 | D13: =(C13-B13)/B13 -> 0.046948357 | E13: =ROUND($B$25/B13,0) -> 7 | F13: =B13*E13 -> 2758.35 | G13: =C13*E13 -> 2887.85 | I13: Market Capitalization < 25000
A14: Deep Industries Ltd | B14: 454.55 | C14: 463.05 | D14: =(C14-B14)/B14 -> 0.018699813 | E14: =ROUND($B$25/B14,0) -> 6 | F14: =B14*E14 -> 2727.3 | G14: =C14*E14 -> 2778.3
A15: Sarda Energy & Minerals Ltd | B15: 496.3 | C15: 508 | D15: =(C15-B15)/B15 -> 0.023574451 | E15: =ROUND($B$25/B15,0) -> 5 | F15: =B15*E15 -> 2481.5 | G15: =C15*E15 -> 2540
A16: Tanla Platforms Ltd | B16: 530.1 | C16: 539.05 | D16: =(C16-B16)/B16 -> 0.016883607 | E16: =ROUND($B$25/B16,0) -> 5 | F16: =B16*E16 -> 2650.5 | G16: =C16*E16 -> 2695.25
A17: Siyaram Silk Mills Ltd | B17: 638.15 | C17: 638.9 | D17: =(C17-B17)/B17 -> 0.0011752723 | E17: =ROUND($B$25/B17,0) -> 4 | F17: =B17*E17 -> 2552.6 | G17: =C17*E17 -> 2555.6
A18: AGI Greenpac Ltd | B18: 689.3 | C18: 707.45 | D18: =(C18-B18)/B18 -> 0.02633106 | E18: =ROUND($B$25/B18,0) -> 4 | F18: =B18*E18 -> 2757.2 | G18: =C18*E18 -> 2829.8
A19: Sharda Cropchem Ltd | B19: 879.45 | C19: 910.65 | D19: =(C19-B19)/B19 -> 0.035476718 | E19: =ROUND($B$25/B19,0) -> 3 | F19: =B19*E19 -> 2638.35 | G19: =C19*E19 -> 2731.95
A20: Chennai Petroleum Corporation Ltd | B20: 1156.3 | C20: 1125.8 | D20: =(C20-B20)/B20 -> -0.026377238 | E20: =ROUND($B$25/B20,0) -> 2 | F20: =B20*E20 -> 2312.6 | G20: =C20*E20 -> 2251.6
A21: Seamec Ltd | B21: 1420.4 | C21: 1431.7 | D21: =(C21-B21)/B21 -> 0.0079555055 | E21: =ROUND($B$25/B21,0) -> 2 | F21: =B21*E21 -> 2840.8 | G21: =C21*E21 -> 2863.4
A22: Great Eastern Shipping Company Ltd | B22: 1483.1 | C22: 1440.4 | D22: =(C22-B22)/B22 -> -0.028791046 | E22: =ROUND($B$25/B22,0) -> 2 | F22: =B22*E22 -> 2966.2 | G22: =C22*E22 -> 2880.8
A23: Bombay Burmah Trading Corporation, Ltd | B23: 1535.2 | C23: 1556.7 | D23: =(C23-B23)/B23 -> 0.01400469 | E23: =ROUND($B$25/B23,0) -> 2 | F23: =B23*E23 -> 3070.4 | G23: =C23*E23 -> 3113.4
A24: Mastek Ltd | B24: 1596.2 | C24: 1621.3 | D24: =(C24-B24)/B24 -> 0.015724847 | E24: =ROUND($B$25/B24,0) -> 2 | F24: =B24*E24 -> 3192.4 | G24: =C24*E24 -> 3242.6
A25: Technocraft Industries (India) Ltd | B25: 2564.9 | C25: 2509.8 | D25: =(C25-B25)/B25 -> -0.021482319 | E25: =ROUND($B$25/B25,0) -> 1 | F25: =B25*E25 -> 2564.9 | G25: =C25*E25 -> 2509.8
A26: Portfolio Total | F26: =SUM(F11:F25) -> 40620.12 | G26: =SUM(G11:G25) -> 41305.65
A28: WEEK 2 SNAPSHOT — 6/30/2026 - 7/10/2026
A29: Reference stock (basis fixed at inception): Hero MotoCorp Ltd (₹4794.3)
A30: Holdings | B30: Total Investment (₹) | D30: Growth (₹) | F30: Return (6/30/2026 - 7/10/2026)
A31: =COUNT(B35:B49) -> 15 | B31: =F50 -> 40620.12 | D31: =G50 -> 41279.96 | F31: =(G50-F50)/F50 -> 0.016244167
A33: HOLDINGS — WEEK 2
A34: Company Name | B34: Day 1 Closing (₹) | C34: 2 Week Closing (₹) | D34: Return (%) | E34: Basis (Shares) | F34: Investment (₹) | G34: Growth (₹)
A35: Indiabulls Ltd | B35: 27.81 | C35: 29.63 | D35: =(C35-B35)/B35 -> 0.065444085 | E35: =ROUND($B$25/B35,0) -> 92 | F35: =B35*E35 -> 2558.52 | G35: =C35*E35 -> 2725.96
A36: Jayaswal Neco Industries Ltd | B36: 84.95 | C36: 84.03 | D36: =(C36-B36)/B36 -> -0.0108299 | E36: =ROUND($B$25/B36,0) -> 30 | F36: =B36*E36 -> 2548.5 | G36: =C36*E36 -> 2520.9
A37: JK Tyre & Industries Ltd | B37: 394.05 | C37: 410.3 | D37: =(C37-B37)/B37 -> 0.041238422 | E37: =ROUND($B$25/B37,0) -> 7 | F37: =B37*E37 -> 2758.35 | G37: =C37*E37 -> 2872.1
A38: Deep Industries Ltd | B38: 454.55 | C38: 465.3 | D38: =(C38-B38)/B38 -> 0.023649764 | E38: =ROUND($B$25/B38,0) -> 6 | F38: =B38*E38 -> 2727.3 | G38: =C38*E38 -> 2791.8
A39: Sarda Energy & Minerals Ltd | B39: 496.3 | C39: 500.95 | D39: =(C39-B39)/B39 -> 0.0093693331 | E39: =ROUND($B$25/B39,0) -> 5 | F39: =B39*E39 -> 2481.5 | G39: =C39*E39 -> 2504.75
A40: Tanla Platforms Ltd | B40: 530.1 | C40: 550.2 | D40: =(C40-B40)/B40 -> 0.037917374 | E40: =ROUND($B$25/B40,0) -> 5 | F40: =B40*E40 -> 2650.5 | G40: =C40*E40 -> 2751
A41: Siyaram Silk Mills Ltd | B41: 638.15 | C41: 645 | D41: =(C41-B41)/B41 -> 0.010734153 | E41: =ROUND($B$25/B41,0) -> 4 | F41: =B41*E41 -> 2552.6 | G41: =C41*E41 -> 2580
A42: AGI Greenpac Ltd | B42: 689.3 | C42: 713.55 | D42: =(C42-B42)/B42 -> 0.035180618 | E42: =ROUND($B$25/B42,0) -> 4 | F42: =B42*E42 -> 2757.2 | G42: =C42*E42 -> 2854.2
A43: Sharda Cropchem Ltd | B43: 879.45 | C43: 914.75 | D43: =(C43-B43)/B43 -> 0.040138723 | E43: =ROUND($B$25/B43,0) -> 3 | F43: =B43*E43 -> 2638.35 | G43: =C43*E43 -> 2744.25
...

Sheet Method Self
A1: PORTFOLIO BASKET TRACKER — METHOD SELF
A2: Student: Vishv Jeet Singh Thakur | Institution: UPES | Weekly Basket Performance Tracking (Basis Fixed at Inception)
A4: WEEK 1 SNAPSHOT — 6/30/2026 - 7/3/2026 | I4: QUERY / SCREENING CRITERIA
A5: Reference stock (basis fixed at inception): Oracle Financial Services Software Ltd (₹10775.5) | I5: FII holding > 1 AND
A6: Holdings | B6: Total Investment (₹) | D6: Growth (₹) | F6: Return (6/30/2026 - 7/3/2026) | I6: Return on equity > 16 AND
A7: =COUNT(B11:B29) -> 19 | B7: =F30 -> 203585.65 | D7: =G30 -> 206647.86 | F7: =(G30-F30)/F30 -> 0.015041384 | I7: Dividend yield > 2 AND
I8: Operating profit > 15 AND
A9: HOLDINGS — WEEK 1 | I9: Market Capitalization > 25000
A10: Company Name | B10: Day 1 Closing (₹) | C10: 1 Week Closing (₹) | D10: Return (%) | E10: Basis (Shares) | F10: Investment (₹) | G10: Growth (₹)
A11: NMDC Ltd | B11: 85.16 | C11: 85.4 | D11: =(C11-B11)/B11 -> 0.0028182245 | E11: =ROUND($B$29/B11,0) -> 127 | F11: =B11*E11 -> 10815.32 | G11: =C11*E11 -> 10845.8
A12: Canara Bank Ltd | B12: 125.52 | C12: 127.19 | D12: =(C12-B12)/B12 -> 0.013304653 | E12: =ROUND($B$29/B12,0) -> 86 | F12: =B12*E12 -> 10794.72 | G12: =C12*E12 -> 10938.34
A13: Indian Oil Corporation Ltd | B13: 139.38 | C13: 141.56 | D13: =(C13-B13)/B13 -> 0.015640695 | E13: =ROUND($B$29/B13,0) -> 77 | F13: =B13*E13 -> 10732.26 | G13: =C13*E13 -> 10900.12
A14: Vedanta Ltd | B14: 280.75 | C14: 280.4 | D14: =(C14-B14)/B14 -> -0.0012466607 | E14: =ROUND($B$29/B14,0) -> 38 | F14: =B14*E14 -> 10668.5 | G14: =C14*E14 -> 10655.2
A15: Petronet LNG Ltd | B15: 280.8 | C15: 275.95 | D15: =(C15-B15)/B15 -> -0.01727208 | E15: =ROUND($B$29/B15,0) -> 38 | F15: =B15*E15 -> 10670.4 | G15: =C15*E15 -> 10486.1
A16: Power Grid Corporation of India Ltd | B16: 286.3 | C16: 287.85 | D16: =(C16-B16)/B16 -> 0.0054139015 | E16: =ROUND($B$29/B16,0) -> 38 | F16: =B16*E16 -> 10879.4 | G16: =C16*E16 -> 10938.3
A17: ITC Ltd | B17: 286.95 | C17: 289.95 | D17: =(C17-B17)/B17 -> 0.010454783 | E17: =ROUND($B$29/B17,0) -> 38 | F17: =B17*E17 -> 10904.1 | G17: =C17*E17 -> 11018.1
A18: Bharat Petroleum Corporation Ltd | B18: 303.55 | C18: 308.15 | D18: =(C18-B18)/B18 -> 0.015154011 | E18: =ROUND($B$29/B18,0) -> 35 | F18: =B18*E18 -> 10624.25 | G18: =C18*E18 -> 10785.25
A19: National Aluminium Co Ltd | B19: 339.6 | C19: 347.6 | D19: =(C19-B19)/B19 -> 0.023557126 | E19: =ROUND($B$29/B19,0) -> 32 | F19: =B19*E19 -> 10867.2 | G19: =C19*E19 -> 11123.2
A20: REC Ltd | B20: 363.8 | C20: 365.15 | D20: =(C20-B20)/B20 -> 0.0037108301 | E20: =ROUND($B$29/B20,0) -> 30 | F20: =B20*E20 -> 10914 | G20: =C20*E20 -> 10954.5
A21: Hindustan Petroleum Corp Ltd | B21: 394.45 | C21: 399.25 | D21: =(C21-B21)/B21 -> 0.012168843 | E21: =ROUND($B$29/B21,0) -> 27 | F21: =B21*E21 -> 10650.15 | G21: =C21*E21 -> 10779.75
A22: Power Finance Corporation Ltd | B22: 424.3 | C22: 425.8 | D22: =(C22-B22)/B22 -> 0.0035352345 | E22: =ROUND($B$29/B22,0) -> 25 | F22: =B22*E22 -> 10607.5 | G22: =C22*E22 -> 10645
... A29: Oracle Financial Services Software Ltd | B29: 10775.5 | C29: 11248 | D29: =(C29-B29)/B29 -> 0.043849473 | E29: =ROUND($B$29/B29,0) -> 1 | F29: =B29*E29 -> 10775.5 | G29: =C29*E29 -> 11248
A30: Portfolio Total | F30: =SUM(F11:F29) -> 203585.65 | G30: =SUM(G11:G29) -> 206647.86
A32: WEEK 2 SNAPSHOT — 6/30/2026 - 7/10/2026
A33: Reference stock (basis fixed at inception): Hero MotoCorp Ltd (₹4794.3)
A34: Holdings | B34: Total Investment (₹) | D34: Growth (₹) | F34: Return (6/30/2026 - 7/10/2026)
A35: =COUNT(B39:B57) -> 19 | B35: =F58 -> 203585.65 | D35: =G58 -> 206788.29 | F35: =(G58-F58)/F58 -> 0.015731168
A37: HOLDINGS — WEEK 2
A38: Company Name | B38: Day 1 Closing (₹) | C38: 2 Week Closing (₹) | D38: Return (%) | E38: Basis (Shares) | F38: Investment (₹) | G38: Growth (₹)
A39: NMDC Ltd | B39: 85.16 | C39: 84.92 | D39: =(C39-B39)/B39 -> -0.0028182245 | E39: =ROUND($B$29/B39,0) -> 127 | F39: =B39*E39 -> 10815.32 | G39: =C39*E39 -> 10784.84
A40: Canara Bank Ltd | B40: 125.52 | C40: 128.78 | D40: =(C40-B40)/B40 -> 0.025971957 | E40: =ROUND($B$29/B40,0) -> 86 | F40: =B40*E40 -> 10794.72 | G40: =C40*E40 -> 11075.08
A41: Indian Oil Corporation Ltd | B41: 139.38 | C41: 138.96 | D41: =(C41-B41)/B41 -> -0.0030133448 | E41: =ROUND($B$29/B41,0) -> 77 | F41: =B41*E41 -> 10732.26 | G41: =C41*E41 -> 10699.92
A42: Vedanta Ltd | B42: 280.75 | C42: 272.55 | D42: =(C42-B42)/B42 -> -0.02920748 | E42: =ROUND($B$29/B42,0) -> 38 | F42: =B42*E42 -> 10668.5 | G42: =C42*E42 -> 10356.9
A43: Petronet LNG Ltd | B43: 280.8 | C43: 278.95 | D43: =(C43-B43)/B43 -> -0.0065883191 | E43: =ROUND($B$29/B43,0) -> 38 | F43: =B43*E43 -> 10670.4 | G43: =C43*E43 -> 10600.1
A44: Power Grid Corporation of India Ltd | B44: 286.3 | C44: 283.1 | D44: =(C44-B44)/B44 -> -0.011177087 | E44: =ROUND($B$29/B44,0) -> 38 | F44: =B44*E44 -> 10879.4 | G44: =C44*E44 -> 10757.8
A45: ITC Ltd | B45: 286.95 | C45: 281.75 | D45: =(C45-B45)/B45 -> -0.018121624 | E45: =ROUND($B$29/B45,0) -> 38 | F45: =B45*E45 -> 10904.1 | G45: =C45*E45 -> 10706.5
A46: Bharat Petroleum Corporation Ltd | B46: 303.55 | C46: 309.75 | D46: =(C46-B46)/B46 -> 0.020424971 | E46: =ROUND($B$29/B46,0) -> 35 | F46: =B46*E46 -> 10624.25 | G46: =C46*E46 -> 10841.25
A47: National Aluminium Co Ltd | B47: 339.6 | C47: 354.85 | D47: =(C47-B47)/B47 -> 0.044905771 | E47: =ROUND($B$29/B47,0) -> 32 | F47: =B47*E47 -> 10867.2 | G47: =C47*E47 -> 11355.2
A48: REC Ltd | B48: 363.8 | C48: 351.95 | D48: =(C48-B48)/B48 -> -0.032572842 | E48: =ROUND($B$29/B48,0) -> 30 | F48: =B48*E48 -> 10914 | G48: =C48*E48 -> 10558.5
A49: Hindustan Petroleum Corp Ltd | B49: 394.45 | C49: 395.3 | D49: =(C49-B49)/B49 -> 0.0021548992 | E49: =ROUND($B$29/B49,0) -> 27 | F49: =B49*E49 -> 10650.15 | G49: =C49*E49 -> 10673.1
...
